Workbook

Sheet 懸念
B2: dev-td環境の懸念
B4: ・最近開発した新機能が入ってない | C4: テストスタート前に上げたい | D4: → | E4: dev-tdにテスト前に上げてもらえないか、木岡さんと相談 【中里】 | I4: 問い合わせ中 | J4: →反映済み
B5: ・タイムスタンプ、解像度検証、PLP、SSO設定、カード明細 がない | C5: テスト1周中に上げたい | D5: → | E5: 富田(秀)が問合せ | F5: https://beartail.slack.com/archives/C02QY42J0UE/p1729752363703969?thread_ts=1728545201.995399&cid=C02QY42J0UE
B6: ・Autifyがない | C6: テスト1周後に共通ステージングに上げればOK | D6: →
B7: ・テックタッチがない | C7: おそらく影響なし（木岡さん） | D7: → | E7: 確認済（木岡さんに）
B8: ・BtoB連携やるべきか | C8: 賢吾さんに対応を依頼中 | D8: → | E8: やらなくてよさそうとのこと
B9: ・TCを見れる環境がない | C9: 賢吾さんに対応を依頼中 | D9: → | E9: 設定済み
B10: ・送付元アドレス検索 | C10: 共通ステージングに反映する | D10: → | E10: 反映済み
C16: 対応が必要なのを赤字にしてます
B17: シート | C17: 概要 | D17: 列 1 | E17: 対象項目 | F17: JIRA
B18: 領収書原本/PLPサイト | C18: 11/06 起票 | E18: https://docs.google.com/spreadsheets/d/16H4dpcCe490b0qpEyv4WCs_w6i2ItiKabXM2BmqNTcY/edit?gid=114354577#gid=114354577&range=N38 | F18: FA-108
C19: 本番不具合なので「外」としました | E19: https://docs.google.com/spreadsheets/d/16H4dpcCe490b0qpEyv4WCs_w6i2ItiKabXM2BmqNTcY/edit?gid=114354577#gid=114354577&range=P170:P173 | F19: KH-4267
B20: 稟議 | C20: 再QAしたけど直ってなかったとこで止まってる | E20: https://docs.google.com/spreadsheets/d/16H4dpcCe490b0qpEyv4WCs_w6i2ItiKabXM2BmqNTcY/edit?gid=1834201177#gid=1834201177&range=N44 | F20: FA-99
B21: 個人設定 | C21: 本番不具合なので「外」としました | E21: https://docs.google.com/spreadsheets/d/16H4dpcCe490b0qpEyv4WCs_w6i2ItiKabXM2BmqNTcY/edit?gid=201285008#gid=201285008&range=M130:O130 | F21: SC-184
B22: システム設定 | C22: 本番不具合なので「外」としました | E22: https://docs.google.com/spreadsheets/d/16H4dpcCe490b0qpEyv4WCs_w6i2ItiKabXM2BmqNTcY/edit?gid=387648503#gid=387648503&range=O54 | F22: SC-185
C23: 木岡さんが経費チームに問い合わせ中 | E23: https://docs.google.com/spreadsheets/d/16H4dpcCe490b0qpEyv4WCs_w6i2ItiKabXM2BmqNTcY/edit?gid=387648503#gid=387648503&range=O308 https://docs.google.com/spreadsheets/d/16H4dpcCe490b0qpEyv4WCs_w6i2ItiKabXM2BmqNTcY/edit?gid=387648503#gid=387648503&range=O645:O648 | F23: FA-107 | H23: ←これがブロック多い
C24: 木岡さんからQAに質問来て回答済み | E24: https://docs.google.com/spreadsheets/d/16H4dpcCe490b0qpEyv4WCs_w6i2ItiKabXM2BmqNTcY/edit?gid=387648503#gid=387648503&range=O1142 | F24: FA-104
C25: 本番不具合なので「外」としました | E25: https://docs.google.com/spreadsheets/d/16H4dpcCe490b0qpEyv4WCs_w6i2ItiKabXM2BmqNTcY/edit?gid=387648503#gid=387648503&range=O1355 | F25: KH-4196
C26: 本番不具合なので「外」としました | E26: https://docs.google.com/spreadsheets/d/16H4dpcCe490b0qpEyv4WCs_w6i2ItiKabXM2BmqNTcY/edit?gid=387648503#gid=387648503&range=O1372 | F26: KH-4248
C27: 本番不具合なので「外」としました | E27: https://docs.google.com/spreadsheets/d/16H4dpcCe490b0qpEyv4WCs_w6i2ItiKabXM2BmqNTcY/edit?gid=387648503#gid=387648503&range=O1412 | F27: KH-4255
B28: 通知 | C28: 木岡さんが対象のチームに確認中 | E28: https://docs.google.com/spreadsheets/d/16H4dpcCe490b0qpEyv4WCs_w6i2ItiKabXM2BmqNTcY/edit?gid=71246066#gid=71246066&range=R108 | F28: FA-105
B29: 共通 | C29: 本番不具合なので「外」としました | E29: https://docs.google.com/spreadsheets/d/16H4dpcCe490b0qpEyv4WCs_w6i2ItiKabXM2BmqNTcY/edit?gid=1880495727#gid=1880495727&range=N33 https://docs.google.com/spreadsheets/d/16H4dpcCe490b0qpEyv4WCs_w6i2ItiKabXM2BmqNTcY/edit?gid=1880495727#gid=1880495727&range=N58 | F29: SC-179
C30: dev-tdでのみ発生していたようなのでクローズしてもいいか木岡さんに相談中 | E30: https://docs.google.com/spreadsheets/d/16H4dpcCe490b0qpEyv4WCs_w6i2ItiKabXM2BmqNTcY/edit?gid=1880495727#gid=1880495727&range=N183 | F30: FA-101
C31: 本番不具合なので「外」としました | E31: https://docs.google.com/spreadsheets/d/16H4dpcCe490b0qpEyv4WCs_w6i2ItiKabXM2BmqNTcY/edit?gid=1880495727#gid=1880495727&range=N219 | F31: KH-4246

Sheet 進捗
B2: テスト進捗 | E2: 目安：150 / 人日 | M2: 残項目数 | N2: 総ケース数 | P2: バグ発生数(起票数) | Q2: バグ発生率
M3: =SUM(F25:H25) -> 0 | N3: =SUM(F25:J25) -> 7228 | Q3: =P3/N3 -> 0
C6: ステータス | D6: 設計レビュー | E6: テスト実行者 | F6: 未 | G6: NG | H6: 保 | I6: OK | J6: 外 | K6: - | P6: 設計担当 | Q6: 担当 | R6: 工数_見積もり
B7: 新規ボタン | C7: 完了 | D7: 未 | E7: 中里/北川 | F7: =countif(indirect($B7&"!$M:$T"),F$6) -> 0 | G7: =countif(indirect($B7&"!$M:$T"),G$6) -> 0 | H7: =countif(indirect($B7&"!$M:$T"),H$6) -> 0 | I7: =countif(indirect($B7&"!$M:$T"),I$6) -> 84 | J7: =countif(indirect($B7&"!$M:$T"),J$6) -> 0 | K7: =countif(indirect($B7&"!$M:$T"),K$6) -> 2296 | P7: +新規 | Q7: 富田(秀) | R7: 0.5 | S7: 作りかけだったので、＋新規→手入力まで作りました（本橋）
B8: 経費 | C8: 完了 | D8: 済 | E8: 行田 | F8: =countif(indirect($B8&"!$N:$T"),F$6) -> 0 | G8: =countif(indirect($B8&"!$N:$T"),G$6) -> 0 | H8: =countif(indirect($B8&"!$N:$T"),H$6) -> 0 | I8: =countif(indirect($B8&"!$N:$T"),I$6) -> 363 | J8: =countif(indirect($B8&"!$N:$T"),J$6) -> 213 | K8: =countif(indirect($B8&"!$N:$T"),K$6) -> 2020 | P8: 申請 | Q8: 富田(秀) | R8: 0.8
B9: カード明細 | C9: 完了 | D9: 済 | E9: 北川 | F9: =countif(indirect($B9&"!$N:$T"),F$6) -> 0 | G9: =countif(indirect($B9&"!$N:$T"),G$6) -> 0 | H9: =countif(indirect($B9&"!$N:$T"),H$6) -> 0 | I9: =countif(indirect($B9&"!$N:$T"),I$6) -> 110 | J9: =countif(indirect($B9&"!$N:$T"),J$6) -> 2 | K9: =countif(indirect($B9&"!$N:$T"),K$6) -> 320 | P9: 承認 | Q9: 富田(秀) | R9: 0.8
B10: 仮払 | C10: 完了 | D10: 済 | E10: 行田 | F10: =countif(indirect($B10&"!$N:$T"),F$6) -> 0 | G10: =countif(indirect($B10&"!$N:$T"),G$6) -> 0 | H10: =countif(indirect($B10&"!$N:$T"),H$6) -> 0 | I10: =countif(indirect($B10&"!$N:$T"),I$6) -> 124 | J10: =countif(indirect($B10&"!$N:$T"),J$6) -> 0 | K10: =countif(indirect($B10&"!$N:$T"),K$6) -> 0 | P10: 経費 | Q10: 本橋 | R10: 1.5
B11: 集計(経費) | C11: 完了 | D11: 済 | E11: 北川/本橋 | F11: =countif(indirect($B11&"!$N:$T"),F$6) -> 0 | G11: =countif(indirect($B11&"!$N:$T"),G$6) -> 0 | H11: =countif(indirect($B11&"!$N:$T"),H$6) -> 0 | I11: =countif(indirect($B11&"!$N:$T"),I$6) -> 326 | J11: =countif(indirect($B11&"!$N:$T"),J$6) -> 23 | K11: =countif(indirect($B11&"!$N:$T"),K$6) -> 739 | P11: カード明細 | Q11: 本橋 | R11: 0.5
B12: 領収書原本/PLPサイト | C12: 完了 | D12: 済 | E12: 金田 | F12: =countif(indirect($B12&"!$N:$T"),F$6) -> 0 | G12: =countif(indirect($B12&"!$N:$T"),G$6) -> 0 | H12: =countif(indirect($B12&"!$N:$T"),H$6) -> 0 | I12: =countif(indirect($B12&"!$N:$T"),I$6) -> 286 | J12: =countif(indirect($B12&"!$N:$T"),J$6) -> 109 | K12: =countif(indirect($B12&"!$N:$T"),K$6) -> 681 | P12: 仮払 | Q12: 本橋 | R12: 0.2
B13: 稟議 | C13: 完了 | D13: 済 | F13: =countif(indirect($B13&"!$N:$T"),F$6) -> 0 | G13: =countif(indirect($B13&"!$N:$T"),G$6) -> 0 | H13: =countif(indirect($B13&"!$N:$T"),H$6) -> 0 | I13: =countif(indirect($B13&"!$N:$T"),I$6) -> 232 | J13: =countif(indirect($B13&"!$N:$T"),J$6) -> 1 | K13: =countif(indirect($B13&"!$N:$T"),K$6) -> 27 | P13: 集計 | Q13: 本橋 | R13: 0.5
B14: 請求書 | C14: 完了 | D14: 済 | E14: 北川 | F14: =countif(indirect($B14&"!$K:$N"),F$6) -> 0 | G14: =countif(indirect($B14&"!$K:$N"),G$6) -> 0 | H14: =countif(indirect($B14&"!$K:$N"),H$6) -> 0 | I14: =countif(indirect($B14&"!$K:$N"),I$6) -> 347 | J14: =countif(indirect($B14&"!$K:$N"),J$6) -> 1 | K14: =countif(indirect($B14&"!$K:$N"),K$6) -> 340 | P14: 領収書原本/PLP | Q14: 本橋 | R14: 0.2
B15: 個人設定 | C15: 完了 | D15: 済 | E15: 中里/行田 | F15: =countif(indirect($B15&"!$M:$T"),F$6) -> 0 | G15: =countif(indirect($B15&"!$M:$T"),G$6) -> 0 | H15: =countif(indirect($B15&"!$M:$T"),H$6) -> 0 | I15: =countif(indirect($B15&"!$M:$T"),I$6) -> 327 | J15: =countif(indirect($B15&"!$M:$T"),J$6) -> 25 | K15: =countif(indirect($B15&"!$M:$T"),K$6) -> 336 | P15: 稟議 | Q15: 中里 | R15: 0.5
B16: 国税関係書類 | C16: 完了 | D16: 済 | E16: 北川 | F16: =countif(indirect($B16&"!$L:$T"),F$6) -> 0 | G16: =countif(indirect($B16&"!$L:$T"),G$6) -> 0 | H16: =countif(indirect($B16&"!$L:$T"),H$6) -> 0 | I16: =countif(indirect($B16&"!$L:$T"),I$6) -> 264 | J16: =countif(indirect($B16&"!$L:$T"),J$6) -> 364 | K16: =countif(indirect($B16&"!$L:$T"),K$6) -> 471 | P16: 自動入力中書類 | Q16: 七浦 | R16: 0.2
B17: 自動入力中書類 | C17: 完了 | D17: 済 | F17: =countif(indirect($B17&"!$K:$T"),F$6) -> 0 | G17: =countif(indirect($B17&"!$K:$T"),G$6) -> 0 | H17: =countif(indirect($B17&"!$K:$T"),H$6) -> 0 | I17: =countif(indirect($B17&"!$K:$T"),I$6) -> 48 | J17: =countif(indirect($B17&"!$K:$T"),J$6) -> 136 | K17: =countif(indirect($B17&"!$K:$T"),K$6) -> 166 | P17: 請求書 | Q17: 中里 | R17: 1.5
B18: 取引先 | C18: 完了 | D18: 済 | E18: 金子 | F18: =countif(indirect($B18&"!$M:$T"),F$6) -> 0 | G18: =countif(indirect($B18&"!$M:$T"),G$6) -> 0 | H18: =countif(indirect($B18&"!$M:$T"),H$6) -> 0 | I18: =countif(indirect($B18&"!$M:$T"),I$6) -> 220 | J18: =countif(indirect($B18&"!$M:$T"),J$6) -> 421 | K18: =countif(indirect($B18&"!$M:$T"),K$6) -> 399 | P18: 国税関係書類 | Q18: 七浦 | R18: 1 | S18: ※旧UIもいる？
B19: 集計(請求書) | C19: 完了 | D19: 済 | E19: 北川 | F19: =countif(indirect($B19&"!$M:$T"),F$6) -> 0 | G19: =countif(indirect($B19&"!$M:$T"),G$6) -> 0 | H19: =countif(indirect($B19&"!$M:$T"),H$6) -> 0 | I19: =countif(indirect($B19&"!$M:$T"),I$6) -> 169 | J19: =countif(indirect($B19&"!$M:$T"),J$6) -> 147 | K19: =countif(indirect($B19&"!$M:$T"),K$6) -> 790 | P19: 取引先 | Q19: 七浦 | R19: 0.8
B20: システム設定 | C20: 完了 | D20: 済 | E20: 金田/北川/七浦/行田/富田（典） | F20: =countif(indirect($B20&"!$O:$R"),F$6) -> 0 | G20: =countif(indirect($B20&"!$O:$R"),G$6) -> 0 | H20: =countif(indirect($B20&"!$O:$R"),H$6) -> 0 | I20: =countif(indirect($B20&"!$O:$R"),I$6) -> 1730 | J20: =countif(indirect($B20&"!$O:$R"),J$6) -> 250 | K20: =countif(indirect($B20&"!$O:$R"),K$6) -> 4456 | L20: 法人カード | P20: 集計 | Q20: 七浦 | R20: 0.5
B21: 通知 | C21: 完了 | D21: 済 | E21: 金田 | F21: =countif(indirect($B21&"!$O:$R"),F$6) -> 0 | G21: =countif(indirect($B21&"!$O:$R"),G$6) -> 0 | H21: =countif(indirect($B21&"!$O:$R"),H$6) -> 0 | I21: =countif(indirect($B21&"!$O:$R"),I$6) -> 107 | J21: =countif(indirect($B21&"!$O:$R"),J$6) -> 0 | K21: =countif(indirect($B21&"!$O:$R"),K$6) -> 0 | L21: 法人カード | P21: システム設定 | Q21: 富田(典) | R21: 2
B22: 申請 | C22: 完了 | D22: 済 | E22: 金子 | F22: =countif(indirect($B22&"!$M:$T"),F$6) -> 0 | G22: =countif(indirect($B22&"!$M:$T"),G$6) -> 0 | H22: =countif(indirect($B22&"!$M:$T"),H$6) -> 0 | I22: =countif(indirect($B22&"!$M:$T"),I$6) -> 258 | J22: =countif(indirect($B22&"!$M:$T"),J$6) -> 25 | K22: =countif(indirect($B22&"!$M:$T"),K$6) -> 801 | P22: 個人設定 | Q22: 中里 | R22: 1
B23: 承認 | C23: 完了 | D23: 済 | E23: 北川 | F23: =countif(indirect($B23&"!$L:$O"),F$6) -> 0 | G23: =countif(indirect($B23&"!$L:$O"),G$6) -> 0 | H23: =countif(indirect($B23&"!$L:$O"),H$6) -> 0 | I23: =countif(indirect($B23&"!$L:$O"),I$6) -> 175 | J23: =countif(indirect($B23&"!$L:$O"),J$6) -> 3 | K23: =countif(indirect($B23&"!$L:$O"),K$6) -> 498 | P23: 通知 | Q23: 富田(典)
B24: 共通 | C24: 完了 | D24: 済 | E24: 富田（典）/本橋 | F24: =countif(indirect($B24&"!$N:$T"),F$6) -> 0 | G24: =countif(indirect($B24&"!$N:$T"),G$6) -> 0 | H24: =countif(indirect($B24&"!$N:$T"),H$6) -> 0 | I24: =countif(indirect($B24&"!$N:$T"),I$6) -> 331 | J24: =countif(indirect($B24&"!$N:$T"),J$6) -> 7 | K24: =countif(indirect($B24&"!$N:$T"),K$6) -> 1014 | P24: 共通コンポーネント | Q24: 本橋
B25: ※B列にシート名を入れると進捗が反映されます | E25: 合計 | F25: =SUM(F7:F24) -> 0 | G25: =SUM(G7:G24) -> 0 | H25: =SUM(H7:H24) -> 0 | I25: =SUM(I7:I24) -> 5501 | J25: =SUM(J7:J24) -> 1727 | K25: =SUM(K7:K24) -> 15354
J26: =I25+J25 -> 7228
C27: 1日の目標消化数(1人)： | D27: 150 | E27: ←～10/30
D28: 90 | E28: ←10/31～
E29: ↓OK+外
B30: 割り当て人数 | C30: 日付 | D30: 消化数(予定) | E30: 消化数(実績) | F30: 総ケース数
C31: 45586 | D31: 0 | E31: 0 | F31: 6970
C32: 45587 | D32: 2500 | E32: 2500 | F32: 6970
B33: 4 | C33: 45588 | D33: 3937 | E33: 3937 | F33: 6970
B34: 5 | C34: 45589 | D34: =D33+B34*$D$27 -> 4687 | E34: 4879 | F34: 6985
B35: 5.5 | C35: 45590 | D35: =D34+B35*$D$27 -> 5512 | E35: 5678 | F35: 7172
B36: 0 | C36: 45591 | D36: =D35+B36*$D$27 -> 5512 | E36: 5678 | F36: 7172
B37: 0 | C37: 45592 | D37: =D36+B37*$D$27 -> 5512 | E37: 5678 | F37: 7172
B38: 2.7 | C38: 45593 | D38: =D37+B38*$D$27 -> 5917 | E38: 5973 | F38: 7172 | G38: =if(E38=0,"",E38-D38) -> 56
B39: 1 | C39: 45594 | D39: =D38+B39*$D$27 -> 6067 | E39: 6058 | F39: 7152 | G39: =if(E39=0,"",E39-D39) -> -9
B40: 3.3 | C40: 45595 | D40: =D39+B40*$D$27 -> 6562 | E40: 6570 | F40: 7230 | G40: =if(E40=0,"",E40-D40) -> 8
B41: 3.9 | C41: 45596 | D41: =D40+B41*$D$28 -> 6913 | E41: 6946 | F41: 7229 | G41: =if(E41=0,"",E41-D41) -> 33
B42: 2.5 | C42: 45597 | D42: =D41+B42*$D$28 -> 7138 | E42: 7130 | F42: 7229 | G42: =if(E42=0,"",E42-D42) -> -8
B43: 0 | C43: 45598 | D43: =D42+B43*$D$28 -> 7138 | E43: 7130 | F43: =$F$42 -> 7229
...

Sheet 共通
N2: Win11/ Chrome | O2: Win11/ Edge | P2: Win11/ Firefox | Q2: Win11/ Safari
B3: No | C3: 画面 | D3: 導線 | E3: 詳細 | K3: テスト実行手順 | L3: 期待値 | M3: 備考 | N3: TK+TI+TD | O3: TK+TI+TD | P3: TK単体 | Q3: TK単体 | R3: 実行者 | S3: 実行備考 | T3: 起票JIRA No
B4: =ROW()-ROW($B$3) -> 1 | C4: プロジェクトを選択モーダル | D4: 経費登録、経費編集、稟議登録、稟議編集、請求書登録、請求書編集、国税関係書類登録、国税関係書類編集 | E4: プロジェクト追加 | F4: プロジェクト名 | K4: プロジェクトを選択モーダルを開く プロジェクト名に任意の入力を行う | L4: 入力できること | N4: OK | O4: - | P4: - | Q4: - | R4: 富田（典）
B5: =ROW()-ROW($B$3) -> 2 | F5: プロジェクトID | K5: プロジェクトIDに任意の入力を行う | L5: 入力できること | N5: OK | O5: - | P5: - | Q5: - | R5: 富田（典）
B6: =ROW()-ROW($B$3) -> 3 | F6: プロジェクトを追加 | K6: プロジェクト名、IDに任意の入力を行う プロジェクトを追加ボタンを押下する 新規登録もしくは編集画面のプロジェクトの欄を確認する | L6: 入力したプロジェクトが追加されること 追加したプロジェクトが表示されていること | N6: OK | O6: - | P6: - | Q6: - | R6: 富田（典）
B7: =ROW()-ROW($B$3) -> 4 | F7: 追加されたプロジェクトの確認 | K7: プロジェクト名、IDに任意の入力を行う プロジェクトを追加ボタンを押下する システム設定>プロジェクトで検索を行う | L7: 追加したプロジェクトが表示されること | N7: OK | O7: - | P7: - | Q7: - | R7: 富田（典）
B8: =ROW()-ROW($B$3) -> 5 | E8: 検索 | F8: 検索欄 | G8: 部分一致 | K8: 検索欄にプロジェクト名の一部を入力する 検索ボタンを押下する | L8: 条件に基づいた検索結果が表示されること | N8: OK | O8: - | P8: - | Q8: - | R8: 富田（典）
B9: =ROW()-ROW($B$3) -> 6 | F9: 検索欄 | G9: 全体一致 | K9: 検索欄にプロジェクト名を入力する 検索ボタンを押下する | L9: 同上 | N9: OK | O9: - | P9: - | Q9: - | R9: 富田（典）
B10: =ROW()-ROW($B$3) -> 7 | F10: 検索欄 | G10: ×ボタン | K10: 検索欄にプロジェクト名を入力する ×ボタンを押下する | L10: 検索欄がクリアされること | N10: OK | O10: - | P10: - | Q10: - | R10: 富田（典）
B11: =ROW()-ROW($B$3) -> 8 | F11: 検索欄 | G11: 検索ボタン | K11: 任意のプロジェクト名を入力する 検索ボタンを押下する | L11: 条件に基づいた検索結果が表示されること | N11: OK | O11: - | P11: - | Q11: - | R11: 富田（典）
B12: =ROW()-ROW($B$3) -> 9 | E12: 選択 | K12: 任意のプロジェクトを選択する 新規登録もしくは編集画面のプロジェクトの欄を確認する | L12: 選択したプロジェクトが反映されていること | N12: OK | O12: - | P12: - | Q12: - | R12: 富田（典）
B13: =ROW()-ROW($B$3) -> 10 | E13: ×ボタン | K13: ×ボタンを押下する | L13: モーダルが閉じること | N13: OK | O13: - | P13: - | Q13: - | R13: 富田（典）
B14: =ROW()-ROW($B$3) -> 11 | E14: モーダル外を押下 | K14: モーダル外を押下する | L14: モーダルが閉じること | N14: OK | O14: - | P14: - | Q14: - | R14: 富田（典）
B15: =ROW()-ROW($B$3) -> 12 | C15: 参加者モーダル | D15: 経費登録、経費編集 | E15: 自社 | F15: 自社の参加者を追加 | G15: ヘッダー(合計人数) | K15: 自社:参加者モーダルを開く 「自社の参加者を追加」横の人数を確認する | L15: 合計人数が表示されていること 内容が正しいこと | N15: OK | O15: - | P15: - | Q15: - | R15: 富田（典）
B16: =ROW()-ROW($B$3) -> 13 | G16: 参加者名 | K16: 参加者名を確認する | L16: 参加者名が表示されていること 内容が正しいこと | N16: OK | O16: - | P16: - | Q16: - | R16: 富田（典） | S16: 内容に齟齬は無いが、参加者一覧での表示順が何に沿ってるのか気になる
B17: =ROW()-ROW($B$3) -> 14 | G17: その他 | H17: 詳細 | I17: 人数 | K17: 社員を追加から任意の人数を追加する その他が追加されることを確認 詳細を確認 | L17: 参加者欄にその他が表示されていること 詳細に人数が表示されていること 人数が正しいこと | N17: OK | O17: - | P17: - | Q17: - | R17: 富田（典）
B18: =ROW()-ROW($B$3) -> 15 | G18: その他 | H18: 詳細 | I18: 人数変更 | J18: ∧ | K18: 参加者名その他の詳細欄を確認 人数の∧ボタンを押下する | L18: 人数が1増えること ヘッダーの合計人数に反映されること | N18: OK | O18: - | P18: - | Q18: - | R18: 富田（典）
B19: =ROW()-ROW($B$3) -> 16 | G19: その他 | H19: 詳細 | I19: 人数変更 | J19: ∨ | K19: 参加者名その他の詳細欄を確認 人数の∨ボタンを押下する | L19: 人数が1減ること ヘッダーの合計人数に反映されること | N19: OK | O19: - | P19: - | Q19: - | R19: 富田（典）
B20: =ROW()-ROW($B$3) -> 17 | G20: その他 | H20: 詳細 | I20: 人数変更 | J20: 直接入力 | K20: 参加者名その他の詳細欄を確認 人数欄に直接数字を入力する | L20: 入力できること ヘッダーの合計人数に反映されること | N20: OK | O20: - | P20: - | Q20: - | R20: 富田（典）
B21: =ROW()-ROW($B$3) -> 18 | G21: その他 | H21: 詳細 | I21: 人数変更 | J21: イレギュラーな数字 | K21: 参加者名その他の詳細欄を確認 人数欄にマイナス、小数点以下、0を入力する | L21: 入力できないこと 反映されないこと | N21: OK | O21: - | P21: - | Q21: - | R21: 富田（典）
B22: =ROW()-ROW($B$3) -> 19 | G22: 除外する | K22: 任意の参加者の除外ボタンを押下する | L22: 除外されること ヘッダーの合計人数に反映されること | N22: OK | O22: - | P22: - | Q22: - | R22: 富田（典）
B23: =ROW()-ROW($B$3) -> 20 | F23: 社員を追加 | G23: 氏名 | K23: 社員を追加＞氏名を選択する 氏名欄に任意の入力を行う 追加ボタンを押下する | L23: 入力した氏名が参加者一覧に追加されること ヘッダーの合計人数に反映されること | N23: OK | O23: - | P23: - | Q23: - | R23: 富田（典）
B24: =ROW()-ROW($B$3) -> 21 | G24: 人数 | H24: 任意の数字 | K24: 社員を追加＞人数を追加する 任意の数字を入力する 追加ボタンを押下する | L24: その他が参加者一覧に追加されること 詳細の人数欄が入力した数値であること ヘッダーの合計人数に反映されること | N24: OK | O24: - | P24: - | Q24: - | R24: 富田（典）
B25: =ROW()-ROW($B$3) -> 22 | G25: 人数 | H25: 小数点以下 | K25: 社員を追加＞人数を追加する 小数点以下の数字を入力する 追加ボタンを押下する | L25: エラーメッセージが表示されること 追加されないこと | N25: OK | O25: - | P25: - | Q25: - | R25: 富田（典） | S25: 0.99999…以下ならエラーとなる。 1以上で小数点以下を含む数値を入力したら、小数点以下は切り捨てで整数部分を読み取って、その他の参加者が追加される
B26: =ROW()-ROW($B$3) -> 23 | G26: 人数 | H26: 既に追加されている場合 | K26: 既にその他が参加者に追加されている状態で 社員を追加＞人数を追加する 追加ボタンを押下する | L26: エラーメッセージが表示されること 追加されないこと | N26: OK | O26: - | P26: - | Q26: - | R26: 富田（典）
B27: =ROW()-ROW($B$3) -> 24 | G27: 人数 | H27: 0以下 | K27: 社員を追加＞人数を追加する 0以下の数字を入力する 追加ボタンを押下する | L27: エラーメッセージが表示されること 追加されないこと | N27: OK | O27: - | P27: - | Q27: - | R27: 富田（典）
B28: =ROW()-ROW($B$3) -> 25 | F28: 自社の社員 | G28: 名前 | H28: 部分一致 | K28: 自社の社員を検索 名前の一部を入力する 検索ボタンを押下する | L28: 条件を満たした検索結果が表示されること | N28: OK | O28: - | P28: - | Q28: - | R28: 富田（典） | S28: 検索時、既に参加者として選択済みの従業員は、検索条件に合わなくても一覧に表示され続ける仕様
B29: =ROW()-ROW($B$3) -> 26 | G29: 名前 | H29: 完全一致 | K29: 自社の社員を検索 名前を入力する 検索ボタンを押下する | L29: 同上 | N29: OK | O29: - | P29: - | Q29: - | R29: 富田（典）
B30: =ROW()-ROW($B$3) -> 27 | G30: 部署 | H30: 部分一致 | K30: 自社の部署を検索 部署名の一部を入力する 検索ボタンを押下する | L30: 同上 | N30: OK | O30: - | P30: - | Q30: - | R30: 富田（典）
B31: =ROW()-ROW($B$3) -> 28 | G31: 部署 | H31: 完全一致 | K31: 自社の部署を検索 部署名を入力する 検索ボタンを押下する | L31: 同上 | N31: OK | O31: - | P31: - | Q31: - | R31: 富田（典）
B32: =ROW()-ROW($B$3) -> 29 | G32: 選択 | K32: 任意の検索を行う 名前、部署の横のボックスを押下する | L32: 選択した氏名、部署が参加者一覧に追加されること | N32: OK | O32: - | P32: - | Q32: - | R32: 富田（典）
B33: =ROW()-ROW($B$3) -> 30 | G33: 削除 | K33: 任意の検索を行う 名前、部署の横のボックスを押下する 削除ボタンを押下する | L33: 削除しますか？モーダルが表示されること 削除を選択すると参加者一覧から削除されること | N33: 外 | O33: - | P33: - | Q33: - | R33: 富田（典） | S33: モーダル内で任意に作成した参加者にのみ、 ごみ箱アイコンが表示される 参加者として✅している状態だと、「削除しました」メッセージが出るが 実際には削除できていない（自社社員一覧の最下部に移動するだけ？） (水木)本番不具合なので対象外とします | T33: https://beartail.atlassian.net/browse/SC-179
B34: =ROW()-ROW($B$3) -> 31 | G34: 検索条件をリセット | K34: 任意の検索を行う 検索条件をリセットボタンを押下する | L34: 検索欄がクリアされること 検索結果がクリアされること | N34: OK | O34: - | P34: - | Q34: - | R34: 富田（典）
B35: =ROW()-ROW($B$3) -> 32 | F35: 表示件数 | K35: 表示件数を変更する | L35: 選択した表示件数になること | N35: OK | O35: - | P35: - | Q35: - | R35: 富田（典）
B36: =ROW()-ROW($B$3) -> 33 | F36: 保存 | K36: 参加者に任意の変更を行う 保存ボタンを押下する | L36: モーダルが閉じること 変更が保存されること | N36: OK | O36: - | P36: - | Q36: - | R36: 富田（典）
B37: =ROW()-ROW($B$3) -> 34 | F37: ×ボタン | K37: ×ボタンを押下する | L37: モーダルが閉じること | N37: OK | O37: - | P37: - | Q37: - | R37: 富田（典）
B38: =ROW()-ROW($B$3) -> 35 | F38: モーダル以外を押下 | K38: モーダル以外の部分を押下する | L38: モーダルが閉じること | N38: OK | O38: - | P38: - | Q38: - | R38: 富田（典）
B39: =ROW()-ROW($B$3) -> 36 | F39: 反映 | K39: 参加者に任意の変更を行う モーダルを閉じる 参加者欄を確認する | L39: 変更が反映されていること | N39: OK | O39: - | P39: - | Q39: - | R39: 富田（典）
B40: =ROW()-ROW($B$3) -> 37 | E40: 取引先 | F40: 取引先の参加者を追加 | G40: ヘッダー(合計人数) | K40: 自社:参加者モーダルを開く 「自社の参加者を追加」横の人数を確認する | L40: 合計人数が表示されていること 内容が正しいこと | N40: OK | O40: - | P40: - | Q40: - | R40: 富田（典） | S40: 手順読み替え 自社→取引先
B41: =ROW()-ROW($B$3) -> 38 | G41: 参加者名 | K41: 参加者名を確認する | L41: 参加者名が表示されていること 内容が正しいこと | N41: OK | O41: - | P41: - | Q41: - | R41: 富田（典）
...

Sheet 本橋作業用
N2: Win11/ Chrome | P2: Win11/ Edge | Q2: Win11/ Firefox | R2: Win11/ Safari
B3: No | C3: 画面 | D3: 確認対象 | E3: 詳細 | K3: テスト実行手順 | L3: 期待値 | M3: 備考 | N3: TK+TI+TD | O3: TK+TD | P3: TI+TD | Q3: TK単体 | R3: TD単体 | S3: 実行者 | T3: 実行備考 | U3: 起票JIRA No
B4: =ROW()-ROW($B$3) -> 1 | C4: 経費一覧 | D4: 経費を登録する | E4: 手入力 | K4: 経費を登録する＞手入力を押下する 任意の設定で経費を登録する | L4: 指定した経費が作成できること 保存した経費に入力した内容が反映されていること | M4: 新規ボタンと共通なので項目は省略 | N4: 未 | O4: 未 | P4: 未 | Q4: 未 | R4: 未
B5: =ROW()-ROW($B$3) -> 2 | C5: 経費一覧 | E5: 交通費入力 | K5: 経費を登録する＞交通費入力を押下する 任意の設定で経費を登録する | L5: - | M5: 新規ボタンと共通なので項目は省略 | N5: 未 | O5: 未 | P5: 未 | Q5: 未 | R5: 未
B6: =ROW()-ROW($B$3) -> 3 | C6: 経費一覧 | E6: 日当 | K6: 経費を登録する＞日当を押下する 任意の設定で経費を登録する | L6: - | M6: 新規ボタンと共通なので項目は省略 | N6: 未 | O6: 未 | P6: 未 | Q6: 未 | R6: 未
B7: =ROW()-ROW($B$3) -> 4 | C7: 経費一覧 | E7: 自動入力 | K7: 経費を登録する＞自動入力を押下する | L7: 自動入力新規登録画面に遷移すること | M7: 新規ボタンと共通なので項目は省略 | N7: 未 | O7: 未 | P7: 未 | Q7: 未 | R7: 未
B8: =ROW()-ROW($B$3) -> 5 | C8: 経費一覧 | D8: 検索条件 | E8: 会社全体 | K8: 左記の検索条件を設定して検索 | L8: 条件に基づいた検索結果が表示されること | N8: 未 | O8: 未 | P8: 未 | Q8: 未 | R8: 未
B9: =ROW()-ROW($B$3) -> 6 | C9: 経費一覧 | E9: 削除済み | G9: - | H9: - | K9: 同上 | L9: 同上 | N9: 未 | O9: 未 | P9: 未 | Q9: 未 | R9: 未
B10: =ROW()-ROW($B$3) -> 7 | C10: 経費一覧 | E10: 従業員 | G10: - | H10: - | K10: 同上 | L10: 同上 | N10: 未 | O10: 未 | P10: 未 | Q10: 未 | R10: 未
B11: =ROW()-ROW($B$3) -> 8 | C11: 経費一覧 | E11: 申請ID | G11: - | H11: - | K11: 同上 | L11: 同上 | N11: 未 | O11: 未 | P11: 未 | Q11: 未 | R11: 未
B12: =ROW()-ROW($B$3) -> 9 | C12: 経費一覧 | E12: 利用日 | F12: 〇〇から | G12: - | H12: - | K12: 同上 | L12: 同上 | N12: 未 | O12: 未 | P12: 未 | Q12: 未 | R12: 未
B13: =ROW()-ROW($B$3) -> 10 | C13: 経費一覧 | F13: 〇〇まで | G13: - | H13: - | K13: 同上 | L13: 同上 | N13: 未 | O13: 未 | P13: 未 | Q13: 未 | R13: 未
B14: =ROW()-ROW($B$3) -> 11 | C14: 経費一覧 | F14: 空白検索 | G14: - | H14: - | K14: 同上 | L14: 同上 | N14: 未 | O14: 未 | P14: 未 | Q14: 未 | R14: 未
B15: =ROW()-ROW($B$3) -> 12 | C15: 経費一覧 | E15: 支払先 | G15: - | H15: - | K15: 同上 | L15: 同上 | N15: 未 | O15: 未 | P15: 未 | Q15: 未 | R15: 未
B16: =ROW()-ROW($B$3) -> 13 | C16: 経費一覧 | F16: 空白検索 | G16: - | H16: - | K16: 同上 | L16: 同上 | N16: 未 | O16: 未 | P16: 未 | Q16: 未 | R16: 未
B17: =ROW()-ROW($B$3) -> 14 | C17: 経費一覧 | E17: 金額 | F17: 〇〇から | G17: - | H17: - | K17: 同上 | L17: 同上 | N17: 未 | O17: 未 | P17: 未 | Q17: 未 | R17: 未
B18: =ROW()-ROW($B$3) -> 15 | C18: 経費一覧 | F18: 〇〇まで | G18: - | H18: - | K18: 同上 | L18: 同上 | N18: 未 | O18: 未 | P18: 未 | Q18: 未 | R18: 未
B19: =ROW()-ROW($B$3) -> 16 | C19: 経費一覧 | F19: 空白検索 | G19: - | H19: - | K19: 同上 | L19: 同上 | N19: 未 | O19: 未 | P19: 未 | Q19: 未 | R19: 未
B20: =ROW()-ROW($B$3) -> 17 | C20: 経費一覧 | E20: 経費科目 | G20: - | H20: - | K20: 同上 | L20: 同上 | N20: 未 | O20: 未 | P20: 未 | Q20: 未 | R20: 未
B21: =ROW()-ROW($B$3) -> 18 | C21: 経費一覧 | E21: 所属部署 | G21: - | H21: - | K21: 同上 | L21: 同上 | N21: 未 | O21: 未 | P21: 未 | Q21: 未 | R21: 未
B22: =ROW()-ROW($B$3) -> 19 | C22: 経費一覧 | F22: 下位部署を含む | G22: - | H22: - | K22: 同上 | L22: 同上 | N22: 未 | O22: 未 | P22: 未 | Q22: 未 | R22: 未
B23: =ROW()-ROW($B$3) -> 20 | C23: 経費一覧 | E23: 精算区分 | F23: 精算対象 | G23: - | H23: - | K23: 同上 | L23: 同上 | N23: 未 | O23: 未 | P23: 未 | Q23: 未 | R23: 未
B24: =ROW()-ROW($B$3) -> 21 | C24: 経費一覧 | F24: 精算対象外 | G24: - | H24: - | K24: 同上 | L24: 同上 | N24: 未 | O24: 未 | P24: 未 | Q24: 未 | R24: 未
B25: =ROW()-ROW($B$3) -> 22 | C25: 経費一覧 | E25: コーポレートカード利用 | F25: あり | G25: - | H25: - | K25: 同上 | L25: 同上 | N25: 未 | O25: 未 | P25: 未 | Q25: 未 | R25: 未
B26: =ROW()-ROW($B$3) -> 23 | C26: 経費一覧 | F26: なし | G26: - | H26: - | K26: 同上 | L26: 同上 | N26: 未 | O26: 未 | P26: 未 | Q26: 未 | R26: 未
B27: =ROW()-ROW($B$3) -> 24 | C27: 経費一覧 | E27: 原本確認 | F27: 確認済み | K27: 同上 | L27: 同上 | N27: 未 | O27: 未 | P27: 未 | Q27: 未 | R27: 未
B28: =ROW()-ROW($B$3) -> 25 | C28: 経費一覧 | F28: 確認済みステータス更新 | K28: 同上 | L28: 同上 | N28: 未 | O28: 未 | P28: 未 | Q28: 未 | R28: 未
B29: =ROW()-ROW($B$3) -> 26 | C29: 経費一覧 | F29: 未確認 | K29: 同上 | L29: 同上 | N29: 未 | O29: 未 | P29: 未 | Q29: 未 | R29: 未
B30: =ROW()-ROW($B$3) -> 27 | C30: 経費一覧 | F30: 不要 | K30: 同上 | L30: 同上 | N30: 未 | O30: 未 | P30: 未 | Q30: 未 | R30: 未
B31: =ROW()-ROW($B$3) -> 28 | C31: 経費一覧 | E31: 出力ID | G31: - | H31: - | K31: 同上 | L31: 同上 | M31: 適当なIDで検索して検索結果が出なければOK | N31: 未 | O31: 未 | P31: 未 | Q31: 未 | R31: 未
B32: =ROW()-ROW($B$3) -> 29 | C32: 経費一覧 | E32: 電子領収書区分 | F32: 電子領収書 | G32: - | H32: - | K32: 同上 | L32: 同上 | N32: 未 | O32: 未 | P32: 未 | Q32: 未 | R32: 未
B33: =ROW()-ROW($B$3) -> 30 | C33: 経費一覧 | F33: 電子領収書以外 | K33: 同上 | L33: 同上 | N33: 未 | O33: 未 | P33: 未 | Q33: 未 | R33: 未
B34: =ROW()-ROW($B$3) -> 31 | C34: 経費一覧 | E34: 汎用マスタ | F34: コード | G34: - | H34: - | K34: 同上 | L34: 同上 | N34: 未 | O34: 未 | P34: 未 | Q34: 未 | R34: 未
B35: =ROW()-ROW($B$3) -> 32 | C35: 経費一覧 | F35: 名称 | K35: 同上 | L35: 同上 | N35: 未 | O35: 未 | P35: 未 | Q35: 未 | R35: 未
B36: =ROW()-ROW($B$3) -> 33 | C36: 経費一覧 | E36: 登録番号 | G36: - | H36: - | K36: 同上 | L36: 同上 | N36: 未 | O36: 未 | P36: 未 | Q36: 未 | R36: 未
B37: =ROW()-ROW($B$3) -> 34 | C37: 経費一覧 | F37: 空白検索 | G37: - | H37: - | K37: 同上 | L37: 同上 | N37: 未 | O37: 未 | P37: 未 | Q37: 未 | R37: 未
B38: =ROW()-ROW($B$3) -> 35 | C38: 経費一覧 | E38: 適格請求書の取り扱い | F38: あり | G38: - | H38: - | K38: 同上 | L38: 同上 | N38: 未 | O38: 未 | P38: 未 | Q38: 未 | R38: 未
B39: =ROW()-ROW($B$3) -> 36 | C39: 経費一覧 | F39: なし | G39: - | H39: - | K39: 同上 | L39: 同上 | N39: 未 | O39: 未 | P39: 未 | Q39: 未 | R39: 未
B40: =ROW()-ROW($B$3) -> 37 | C40: 経費一覧 | E40: ステータス | F40: 未申請 | G40: - | H40: - | K40: 同上 | L40: 同上 | N40: 未 | O40: 未 | P40: 未 | Q40: 未 | R40: 未
B41: =ROW()-ROW($B$3) -> 38 | C41: 経費一覧 | F41: 下書き保存中の申請を含める | G41: - | H41: - | K41: 同上 | L41: 同上 | N41: 未 | O41: 未 | P41: 未 | Q41: 未 | R41: 未
...

Sheet 新規ボタン
C2: ↓「+新規」ボタン の導線を確認 | M2: Win11/ Chrome | N2: Win11/ Edge | O2: Win11/ Firefox | P2: Win11/ Safari
B3: No | C3: 画面 | D3: 確認対象 | E3: 詳細 | J3: テスト実行手順 | K3: 期待値 | L3: 備考 | M3: TK+TI+TD | N3: TK+TI+TD | O3: TI+TD | P3: TK単体 | Q3: 実行者 | R3: 実行備考 | S3: 起票JIRA No
B4: =ROW()-ROW($B$3) -> 1 | C4: 経費精算 | D4: 経費を選択して申請する | E4: 今月分を選択する | K4: 今月分のデータのみ✅がつく | M4: OK | N4: - | O4: - | P4: - | Q4: 中里
B5: =ROW()-ROW($B$3) -> 2 | E5: 先月分を選択する | K5: 先月分のデータのみ✅がつく | M5: OK | N5: - | O5: - | P5: - | Q5: 中里
B6: =ROW()-ROW($B$3) -> 3 | E6: プロジェクトから選択する | K6: 選んだプロジェクトのデータのみ✅がつく | M6: OK | N6: - | O6: - | P6: - | Q6: 中里
B7: =ROW()-ROW($B$3) -> 4 | E7: 請求書先から選択 | F7: 自分(精算対象) | K7: 精算対象のデータに✅がつくこと | M7: OK | N7: - | O7: - | P7: - | Q7: 中里
B8: =ROW()-ROW($B$3) -> 5 | F8: 法人 | K8: 精算対象外のデータに✅がつく | M8: OK | N8: - | O8: - | P8: - | Q8: 中里
B9: =ROW()-ROW($B$3) -> 6 | E9: 選択した経費を編集するボタン | F9: チェックなし | K9: ボタンが非活性 | M9: OK | N9: - | O9: - | P9: - | Q9: 中里
B10: =ROW()-ROW($B$3) -> 7 | F10: チェックあり | K10: ・ボタンが活性 ・一括編集できること | M10: OK | N10: - | O10: - | P10: - | Q10: 中里
B11: =ROW()-ROW($B$3) -> 8 | E11: ソート | F11: 利用日 | J11: 左記の表示項目を設定する 表示項目横の▲▼アイコンを押下する | K11: 昇順降順が切り替わること 設定に応じて表示順が変わること | M11: OK | N11: - | O11: - | P11: - | Q11: 中里
B12: =ROW()-ROW($B$3) -> 9 | F12: 支払先/訪問先 | J12: 同上 | K12: 同上 | M12: OK | N12: - | O12: - | P12: - | Q12: 中里
B13: =ROW()-ROW($B$3) -> 10 | F13: 金額 | J13: 同上 | K13: 同上 | M13: OK | N13: - | O13: - | P13: - | Q13: 中里
B14: =ROW()-ROW($B$3) -> 11 | F14: 経費科目 | J14: 同上 | K14: 同上 | M14: OK | N14: - | O14: - | P14: - | Q14: 中里
B15: =ROW()-ROW($B$3) -> 12 | F15: 所属部署 | J15: 同上 | K15: 同上 | M15: OK | N15: - | O15: - | P15: - | Q15: 中里
B16: =ROW()-ROW($B$3) -> 13 | F16: 経費申請書名 | J16: 同上 | K16: 同上 | M16: OK | N16: - | O16: - | P16: - | Q16: 中里
B17: =ROW()-ROW($B$3) -> 14 | F17: ステータス | J17: 同上 | K17: 同上 | M17: OK | N17: - | O17: - | P17: - | Q17: 中里
B18: =ROW()-ROW($B$3) -> 15 | F18: 登録日 | J18: 同上 | K18: 同上 | M18: OK | N18: - | O18: - | P18: - | Q18: 中里
B19: =ROW()-ROW($B$3) -> 16 | F19: プロジェクト | J19: 同上 | K19: 同上 | M19: OK | N19: - | O19: - | P19: - | Q19: 中里
B20: =ROW()-ROW($B$3) -> 17 | E20: 経費一覧を押下 | K20: 経費詳細が開かれること | M20: OK | N20: - | O20: - | P20: - | Q20: 中里
B21: =ROW()-ROW($B$3) -> 18 | E21: 経費一覧の表示項目 | F21: アラート | G21: タイムスタンプ | J21: 左記の表示項目を設定する タイムスタンプが押された経費の表示項目を確認する アイコンをマウスオーバーする | K21: タイムスタンプのアイコンが表示されること マウスオーバーすると設定に応じて以下が表示されること 「表面/裏面,ver.日付.日時」 | M21: OK | N21: - | O21: - | P21: - | Q21: 北川 | R21: dev-tdではタイムスタンプ確認不可
B22: =ROW()-ROW($B$3) -> 19 | G22: 警告アラート | J22: 左記の表示項目を設定する 警告アラートの条件を満たした経費の表示項目を確認する アイコンをマウスオーバーする | K22: 警告アラートのアイコンが表示されること マウスオーバーすると警告の内容が表示されること | M22: OK | N22: - | O22: - | P22: - | Q22: 中里
B23: =ROW()-ROW($B$3) -> 20 | G23: 申請不可アラート | J23: 左記の表示項目を設定する 申請不可アラートの条件を満たした経費の表示項目を確認する アイコンをマウスオーバーする | K23: 申請不可アラートのアイコンが表示されること マウスオーバーすると申請不可である理由が表示されること | M23: OK | N23: - | O23: - | P23: - | Q23: 中里
B24: =ROW()-ROW($B$3) -> 21 | G24: なし | J24: 左記の表示項目を設定する アラートの条件を満たさない経費を設定して確認する | K24: アラートアイコンが何も表示されていないこと | M24: OK | N24: - | O24: - | P24: - | Q24: 中里
B25: =ROW()-ROW($B$3) -> 22 | F25: 利用日 | G25: 任意の日付 | J25: 左記の表示項目を設定する 経費に任意の日付を設定する 経費一覧の表示項目を確認する | K25: 任意の日付が表示されること | M25: OK | N25: - | O25: - | P25: - | Q25: 中里
B26: =ROW()-ROW($B$3) -> 23 | F26: ラベル | G26: サムネイル画像 | J26: 左記の表示項目を設定する 左記の条件を満たす経費を作成する 経費一覧の表示項目を確認する アイコンをマウスオーバーする | K26: 該当のアイコンが表示されること マウスオーバーすると経費に設定した領収書画像のサムネイル画像が表示されること | M26: OK | N26: - | O26: - | P26: - | Q26: 中里
B27: =ROW()-ROW($B$3) -> 24 | G27: 自動入力された経費 | J27: 同上 | K27: 該当のアイコンが表示されること マウスオーバーした時内容がわかる文言が表示されること | M27: OK | N27: - | O27: - | P27: - | Q27: 北川
B28: =ROW()-ROW($B$3) -> 25 | G28: 外貨を利用した経費 | J28: 同上 | K28: 同上 | M28: OK | N28: - | O28: - | P28: - | Q28: 中里
B29: =ROW()-ROW($B$3) -> 26 | G29: 電子領収書 | J29: 同上 | K29: 同上 | M29: OK | N29: - | O29: - | P29: - | Q29: 中里
B30: =ROW()-ROW($B$3) -> 27 | G30: 精算対象外 | J30: 同上 | K30: 同上 | M30: OK | N30: - | O30: - | P30: - | Q30: 中里
B31: =ROW()-ROW($B$3) -> 28 | G31: カード連携 | J31: 同上 | K31: 同上 | M31: OK | N31: - | O31: - | P31: - | Q31: 北川 | R31: dev-tdでカード明細が実施不可 「関連するカード連携のデータが存在します」
B32: =ROW()-ROW($B$3) -> 29 | G32: 参加者 | J32: 同上 | K32: 同上 | M32: OK | N32: - | O32: - | P32: - | Q32: 中里
B33: =ROW()-ROW($B$3) -> 30 | G33: メモ | J33: 同上 | K33: 同上 | M33: OK | N33: - | O33: - | P33: - | Q33: 中里
B34: =ROW()-ROW($B$3) -> 31 | G34: タイムスタンプ付与失敗 | J34: 領収書画像でタイムスタンプの付与に失敗した経費を用意する 経費一覧の表示項目を確認する アイコンをマウスオーバーする | K34: 同上 | L34: Pass付PDFをアップロードする | M34: OK | N34: - | O34: - | P34: - | Q34: 北川 | R34: dev-tdではタイムスタンプ確認不可 「領収書画像へのタイムスタンプ付与に失敗しました。お手数ですがもう一度アップロードしてください」
B35: =ROW()-ROW($B$3) -> 32 | F35: 電子領収書 | G35: チェック | J35: 左記の表示項目を設定する 経費に左記の設定を行う 経費一覧で該当の経費の表示項目を確認する | K35: 左記の表示項目が一覧に表示されること | M35: OK | N35: - | O35: - | P35: - | Q35: 中里
B36: =ROW()-ROW($B$3) -> 33 | F36: 支払先/訪問先 | G36: 任意の設定 | J36: 同上 | K36: 同上 | M36: OK | N36: - | O36: - | P36: - | Q36: 中里
B37: =ROW()-ROW($B$3) -> 34 | F37: 金額 | G37: 任意の設定 | J37: 同上 | K37: 同上 | M37: OK | N37: - | O37: - | P37: - | Q37: 中里
B38: =ROW()-ROW($B$3) -> 35 | F38: 経費科目 | G38: 任意の設定 | J38: 同上 | K38: 同上 | M38: OK | N38: - | O38: - | P38: - | Q38: 中里
B39: =ROW()-ROW($B$3) -> 36 | F39: 税区分 | G39: 任意の設定 | J39: 同上 | K39: 同上 | M39: OK | N39: - | O39: - | P39: - | Q39: 中里
B40: =ROW()-ROW($B$3) -> 37 | F40: 所属部署 | G40: 任意の設定 | J40: 同上 | K40: 同上 | M40: OK | N40: - | O40: - | P40: - | Q40: 中里
B41: =ROW()-ROW($B$3) -> 38 | F41: 費用負担部署 | G41: 任意の設定 | J41: 同上 | K41: 同上 | M41: OK | N41: - | O41: - | P41: - | Q41: 中里
...

Sheet 集計(経費)
N2: Win11/ Chrome | O2: Win11/ Edge | P2: Win11/ Firefox | Q2: MacOS/ Safari
B3: No | C3: 画面 | D3: 確認対象 | E3: 詳細 | K3: テスト実行手順 | L3: 期待値 | M3: 備考 | N3: TK+TI+TD | O3: TK+TI+TD | P3: TK単体 | Q3: TK単体 | R3: 実行者 | S3: 実行備考 | T3: 起票JIRA No
B4: =ROW()-ROW($B$3) -> 1 | C4: 集計画面(TK) | D4: 集計履歴 | E4: 経費申請タブ | K4: 集計一覧を開く 左記のタブを確認 左記のタブを押下 | L4: タブの横に表示件数が表示されること タブが切り替わること | N4: OK | O4: OK | P4: OK | Q4: OK | R4: 北川
B5: =ROW()-ROW($B$3) -> 2 | C5: 集計画面(TK) | E5: 事前申請タブ | K5: 同上 | L5: 同上 | N5: OK | O5: OK | P5: OK | Q5: OK | R5: 北川
B6: =ROW()-ROW($B$3) -> 3 | C6: 集計画面(TK) | E6: 旅費申請タブ | K6: 同上 | L6: 同上 | N6: OK | O6: OK | P6: OK | Q6: OK | R6: 北川
B7: =ROW()-ROW($B$3) -> 4 | C7: 集計画面(TK) | E7: 検索条件を設定 | K7: 検索条件を設定を押下して展開 任意の検索設定を設定する | L7: 任意の検索設定が設定できること | N7: OK | O7: OK | P7: OK | Q7: OK | R7: 北川
B8: =ROW()-ROW($B$3) -> 5 | C8: 集計画面(TK) | E8: 検索条件をリセット | K8: 検索条件をリセットを押下 | L8: 検索設定がリセットされること | N8: OK | O8: OK | P8: OK | Q8: OK | R8: 北川
B9: =ROW()-ROW($B$3) -> 6 | C9: 集計画面(TK) | E9: この条件で検索 | K9: 任意の設定で検索 | L9: 設定に基づいた検索結果が表示されること | N9: OK | O9: - | P9: - | Q9: - | R9: 本橋
B10: =ROW()-ROW($B$3) -> 7 | C10: 集計画面(TK) | F10: 作成日時～から | K10: 左記の設定を入力して検索 | L10: 同上 | N10: OK | O10: - | P10: - | Q10: - | R10: 本橋
B11: =ROW()-ROW($B$3) -> 8 | C11: 集計画面(TK) | F11: 作成日時～まで | K11: 同上 | L11: 同上 | N11: OK | O11: - | P11: - | Q11: - | R11: 本橋
B12: =ROW()-ROW($B$3) -> 9 | C12: 集計画面(TK) | F12: 総額～から | K12: 同上 | L12: 同上 | N12: OK | O12: - | P12: - | Q12: - | R12: 本橋
B13: =ROW()-ROW($B$3) -> 10 | C13: 集計画面(TK) | F13: 総額～まで | K13: 同上 | L13: 同上 | N13: OK | O13: - | P13: - | Q13: - | R13: 本橋
B14: =ROW()-ROW($B$3) -> 11 | C14: 集計画面(TK) | F14: 集計名 | K14: 同上 | L14: 同上 | N14: OK | O14: - | P14: - | Q14: - | R14: 本橋
B15: =ROW()-ROW($B$3) -> 12 | C15: 集計画面(TK) | F15: 支払ステータス:処理済み | K15: 同上 | L15: 同上 | N15: OK | O15: - | P15: - | Q15: - | R15: 本橋
B16: =ROW()-ROW($B$3) -> 13 | C16: 集計画面(TK) | F16: 支払ステータス:未払い | K16: 同上 | L16: 同上 | N16: OK | O16: - | P16: - | Q16: - | R16: 本橋
B17: =ROW()-ROW($B$3) -> 14 | C17: 集計画面(TK) | F17: 会計データ出力:出力済み | K17: 同上 | L17: 同上 | N17: OK | O17: - | P17: - | Q17: - | R17: 本橋
B18: =ROW()-ROW($B$3) -> 15 | C18: 集計画面(TK) | F18: 会計データ出力:未出力 | K18: 同上 | L18: 同上 | N18: OK | O18: - | P18: - | Q18: - | R18: 本橋
B19: =ROW()-ROW($B$3) -> 16 | C19: 集計画面(TK) | E19: ページネーション | F19: ページ指定 | K19: 任意のページを押下する | L19: 指定したページに移動すること | N19: OK | O19: - | P19: - | Q19: - | R19: 北川
B20: =ROW()-ROW($B$3) -> 17 | C20: 集計画面(TK) | F20: > | K20: >を押下する | L20: 指定したページに移動すること | N20: OK | O20: - | P20: - | Q20: - | R20: 北川
B21: =ROW()-ROW($B$3) -> 18 | C21: 集計画面(TK) | F21: >> | K21: >>を押下する | L21: 最後尾のページに移動すること | M21: 表示には51件以上の蓄積が必要 | N21: OK | O21: - | P21: - | Q21: - | R21: 北川
B22: =ROW()-ROW($B$3) -> 19 | C22: 集計画面(TK) | F22: < | K22: <を押下する | L22: 指定したページに移動すること | N22: OK | O22: - | P22: - | Q22: - | R22: 北川
B23: =ROW()-ROW($B$3) -> 20 | C23: 集計画面(TK) | F23: << | K23: <<を押下する | L23: 先頭のページに移動すること | M23: 表示には51件以上の蓄積が必要 | N23: OK | O23: - | P23: - | Q23: - | R23: 北川
B24: =ROW()-ROW($B$3) -> 21 | C24: 集計画面(TK) | E24: 表示件数 | K24: 表示件数を押下する 任意の件数に変更する | L24: 表示件数が切り替わること | N24: OK | O24: - | P24: - | Q24: - | R24: 北川
B25: =ROW()-ROW($B$3) -> 22 | C25: 集計画面(TK) | E25: ソート | F25: 経費申請 | G25: 作成日時 | K25: 左記の▲▼アイコンを押下 | L25: 昇順降順が切り替わり、設定した順序に並び変わること | N25: OK | O25: OK | P25: - | Q25: - | R25: 北川
B26: =ROW()-ROW($B$3) -> 23 | C26: 集計画面(TK) | G26: 集計名 | K26: 同上 | L26: 同上 | N26: OK | O26: OK | P26: - | Q26: - | R26: 北川
B27: =ROW()-ROW($B$3) -> 24 | C27: 集計画面(TK) | F27: 事前申請（仮払） | G27: 作成日時 | K27: 同上 | L27: 同上 | N27: OK | O27: OK | P27: - | Q27: - | R27: 北川
B28: =ROW()-ROW($B$3) -> 25 | C28: 集計画面(TK) | G28: 集計名 | K28: 同上 | L28: 同上 | N28: OK | O28: OK | P28: - | Q28: - | R28: 北川
B29: =ROW()-ROW($B$3) -> 26 | C29: 集計画面(TK) | F29: 旅費申請 | G29: 作成日時 | K29: 同上 | L29: 同上 | N29: OK | O29: OK | P29: - | Q29: - | R29: 北川
B30: =ROW()-ROW($B$3) -> 27 | C30: 集計画面(TK) | G30: 集計名 | K30: 同上 | L30: 同上 | N30: OK | O30: OK | P30: - | Q30: - | R30: 北川
B31: =ROW()-ROW($B$3) -> 28 | C31: 集計画面(TK) | E31: 表示項目 | F31: 経費申請 | G31: 作成日時 | K31: 左記の表示項目を確認する 任意の集計詳細を開き内容を確認する | L31: 左記の表示項目が表示されていること 項目の内容が正しいこと | N31: OK | O31: OK | P31: - | Q31: - | R31: 本橋
B32: =ROW()-ROW($B$3) -> 29 | C32: 集計画面(TK) | G32: 集計名 | K32: 同上 | L32: 同上 | N32: OK | O32: OK | P32: - | Q32: - | R32: 本橋
B33: =ROW()-ROW($B$3) -> 30 | C33: 集計画面(TK) | G33: 支払ステータス | K33: 同上 | L33: 同上 | N33: OK | O33: OK | P33: - | Q33: - | R33: 本橋
B34: =ROW()-ROW($B$3) -> 31 | C34: 集計画面(TK) | G34: 集計方法 | K34: 同上 | L34: 同上 | N34: OK | O34: OK | P34: - | Q34: - | R34: 本橋 | S34: 会計データ出力のオプションが必要
B35: =ROW()-ROW($B$3) -> 32 | C35: 集計画面(TK) | G35: 会計データ出力 | K35: 同上 | L35: 同上 | N35: OK | O35: OK | P35: - | Q35: - | R35: 本橋
B36: =ROW()-ROW($B$3) -> 33 | C36: 集計画面(TK) | G36: 経費数 | K36: 同上 | L36: 同上 | N36: OK | O36: OK | P36: - | Q36: - | R36: 本橋
B37: =ROW()-ROW($B$3) -> 34 | C37: 集計画面(TK) | G37: 総額 | K37: 同上 | L37: 同上 | N37: OK | O37: OK | P37: - | Q37: - | R37: 本橋
B38: =ROW()-ROW($B$3) -> 35 | C38: 集計画面(TK) | G38: 削除ボタン | K38: 削除ボタンを押下する | L38: 任意の集計が削除されること | N38: OK | O38: OK | P38: - | Q38: - | R38: 本橋
B39: =ROW()-ROW($B$3) -> 36 | C39: 集計画面(TK) | F39: 事前申請（仮払） | G39: 作成日時 | K39: 左記の表示項目を確認する 任意の集計詳細を開き内容を確認する | L39: 左記の表示項目が表示されていること 項目の内容が正しいこと | N39: OK | O39: OK | P39: - | Q39: - | R39: 本橋
B40: =ROW()-ROW($B$3) -> 37 | C40: 集計画面(TK) | G40: 集計名 | K40: 同上 | L40: 同上 | N40: OK | O40: OK | P40: - | Q40: - | R40: 本橋
B41: =ROW()-ROW($B$3) -> 38 | C41: 集計画面(TK) | G41: 支払ステータス | K41: 同上 | L41: 同上 | N41: OK | O41: OK | P41: - | Q41: - | R41: 本橋
...

Sheet 申請
M2: Win11/ Chrome | N2: Win11/ Edge | O2: Win11/ Firefox | P2: Win11/ Safari
B3: No | C3: 画面 | D3: 確認対象 | E3: 項目3 | F3: 項目4 | G3: 項目5 | H3: 項目6 | I3: 項目7 | J3: テスト実行手順 | K3: 期待値 | L3: 備考 | M3: TK+TI+TD | N3: TI+TD | O3: TI+TD | P3: TK単体 | Q3: 実行者 | R3: 実行備考 | S3: 起票JIRA No
B4: =ROW()-ROW($B$3) -> 1 | C4: 申請一覧 | D4: 申請するボタン | E4: 経費精算 | J4: 1.申請するボタンから経費精算を選ぶ 2.経費一覧が出るので任意の経費を選び、「選択した経費を申請する」を押下 3.申請書名を入力モーダル→完了ボタンを押下 4.申請内容を確認モーダル→申請するボタンを押下 | K4: 申請詳細へ遷移 | M4: OK | N4: - | O4: - | P4: OK | Q4: 金子 金田
B5: =ROW()-ROW($B$3) -> 2 | E5: 事前申請 | J5: 1.申請するボタンから事前申請を選ぶ →事前申請作成画面へ遷移される 3.事前申請内容＆事前申請項目を入力 3.保存して申請するを押下 | K5: 申請詳細へ遷移 | M5: OK | N5: - | O5: - | P5: OK | Q5: 金子 金田
B6: =ROW()-ROW($B$3) -> 3 | E6: 汎用申請 | J6: 1.申請するボタンから汎用申請を選ぶ 2.汎用申請作成画面が遷移され、任意の項目入力後に「申請する」を押下 3.申請モーダル→申請を提出ボタンを押下 | K6: 申請詳細へ遷移 | M6: OK | N6: - | O6: - | P6: OK | Q6: 金子 金田
B7: =ROW()-ROW($B$3) -> 4 | E7: 支払依頼申請 | J7: 1.申請するボタンから支払依頼申請を選ぶ | K7: 請求書一覧へ遷移 | M7: OK | N7: OK | O7: OK | P7: - | Q7: 金子 金田
B8: =ROW()-ROW($B$3) -> 5 | E8: 稟議申請 | J8: 1.申請するボタンから稟議申請を選ぶ | K8: 発注稟議作成画面へ遷移 | M8: OK | N8: OK | O8: OK | P8: - | Q8: 金子 金田
B9: =ROW()-ROW($B$3) -> 6 | E9: 一括支払依頼申請 | J9: 1.申請するボタンから一括支払依頼申請を選ぶ | K9: 請求書一覧へ遷移 | M9: OK | N9: OK | O9: OK | P9: - | Q9: 金子 金田
B10: =ROW()-ROW($B$3) -> 7 | D10: 検索条件を指定 | E10: 経費精算タブ | J10: 任意の項目で検索 | K10: 検索通りに絞り込めること | M10: OK | N10: - | O10: - | P10: - | Q10: 金子
B11: =ROW()-ROW($B$3) -> 8 | E11: 事前申請タブ | J11: 任意の項目で検索 | K11: 検索通りに絞り込めること | M11: OK | N11: - | O11: - | P11: - | Q11: 金子
B12: =ROW()-ROW($B$3) -> 9 | E12: 汎用申請タブ | J12: 任意の項目で検索 | K12: 検索通りに絞り込めること | M12: OK | N12: - | O12: - | P12: - | Q12: 金子
B13: =ROW()-ROW($B$3) -> 10 | E13: 支払依頼申請タブ | J13: 任意の項目で検索 | K13: 検索通りに絞り込めること | M13: OK | N13: - | O13: - | P13: - | Q13: 金子
B14: =ROW()-ROW($B$3) -> 11 | E14: 稟議申請タブ | J14: 任意の項目で検索 | K14: 検索通りに絞り込めること | M14: OK | N14: - | O14: - | P14: - | Q14: 金子
B15: =ROW()-ROW($B$3) -> 12 | E15: 一括支払依頼申請 | J15: 任意の項目で検索 | K15: 検索通りに絞り込めること | M15: OK | N15: - | O15: - | P15: - | Q15: 金子
B16: =ROW()-ROW($B$3) -> 13 | D16: 検索条件をリセット | J16: 検索条件をリセットを押下 | K16: リセットできること | M16: OK | N16: - | O16: - | P16: - | Q16: 金子
B17: =ROW()-ROW($B$3) -> 14 | D17: 経費精算タブ | E17: 表示項目設定 | J17: 任意の項目で表示項目設定する | K17: 設定どおりに一覧が最新化されること | M17: OK | N17: - | O17: - | P17: - | Q17: 金子
B18: =ROW()-ROW($B$3) -> 15 | E18: ソートボタン | F18: 申請ID | J18: 申請IDカラムのソートボタンを押下 | K18: 一覧がID順になること | M18: OK | N18: - | O18: - | P18: - | Q18: 金子
B19: =ROW()-ROW($B$3) -> 16 | F19: 申請種別 | J19: 1.申請種別カラムを押下 2.経費申請、精算(仮払以外)、精算(仮払)の✅を外す | K19: 外したものが一覧から外れること | M19: OK | N19: - | O19: - | P19: - | Q19: 金子
B20: =ROW()-ROW($B$3) -> 17 | E20: 申請状況 | F20: 未申請 | J20: 1.経費を下書き保存する 2.申請一覧を確認 | K20: 未申請ステータスになること | M20: OK | N20: - | O20: - | P20: - | Q20: 金子
B21: =ROW()-ROW($B$3) -> 18 | F21: 承認待ち | J21: 1.経費申請する 2.申請一覧を確認 | K21: 承認待ちステータスになること | M21: OK | N21: - | O21: - | P21: - | Q21: 金子
B22: =ROW()-ROW($B$3) -> 19 | F22: 取下げ | J22: 1.経費を取り下げる 2.申請一覧を確認 | K22: 取下げステータスになること | M22: OK | N22: - | O22: - | P22: - | Q22: 金子
B23: =ROW()-ROW($B$3) -> 20 | F23: 差し戻し | J23: 1.(承認者が)経費を差し戻す 2.申請一覧を確認 | K23: 差し戻しステータスになること | M23: OK | N23: - | O23: - | P23: - | Q23: 金子
B24: =ROW()-ROW($B$3) -> 21 | F24: フロー変更待ち | J24: 1.経費申請後に当該申請フローを変更する 2.申請一覧を確認 | K24: フロー変更待ちステータスになること | M24: OK | N24: - | O24: - | P24: - | Q24: 金子
B25: =ROW()-ROW($B$3) -> 22 | F25: 承認済み | J25: 1.経費申請する 2.(承認者が)承認する 3.申請一覧を確認 | K25: 承認待ちステータスになること | M25: OK | N25: - | O25: - | P25: - | Q25: 金子
B26: =ROW()-ROW($B$3) -> 23 | F26: 支払処理済み | J26: 1.経費申請する 2.(承認者が)承認する 3.(集計者が)支払処理する 4.申請一覧を確認 | K26: 支払処理済みステータスになること | M26: OK | N26: - | O26: - | P26: - | Q26: 金子
B27: =ROW()-ROW($B$3) -> 24 | E27: 出力ボタン | F27: 精算申請書出力 | K27: 精算申請書をダウンロードできること | M27: OK | N27: - | O27: - | P27: - | Q27: 金子
B28: =ROW()-ROW($B$3) -> 25 | F28: 会計データ出力 | G28: 任意のフォーマット | H28: メールで送信 | K28: メールで通知されること | M28: OK | N28: - | O28: - | P28: - | Q28: 金子
B29: =ROW()-ROW($B$3) -> 26 | H29: ダウンロード | K29: 会計データが出力されること | M29: OK | N29: - | O29: - | P29: - | Q29: 金子
B30: =ROW()-ROW($B$3) -> 27 | E30: 削除ボタン | K30: 削除できること | M30: OK | N30: - | O30: - | P30: - | Q30: 金子
B31: =ROW()-ROW($B$3) -> 28 | E31: 表示件数 | K31: 表示件数を変更できること | M31: OK | N31: - | O31: - | P31: - | Q31: 金田
B32: =ROW()-ROW($B$3) -> 29 | E32: ページネーション | F32: 数字のボタン | K32: 押下した通りにページ遷移できること | M32: OK | N32: - | O32: - | P32: - | Q32: 金田
B33: =ROW()-ROW($B$3) -> 30 | F33: 「>」ボタン | K33: 押下した通りにページ遷移できること | M33: OK | N33: - | O33: - | P33: - | Q33: 金田
B34: =ROW()-ROW($B$3) -> 31 | F34: 「<」ボタン | K34: 押下した通りにページ遷移できること | M34: OK | N34: - | O34: - | P34: - | Q34: 金田
B35: =ROW()-ROW($B$3) -> 32 | F35: 「>>」ボタン | K35: 押下した通りにページ遷移できること | M35: OK | N35: - | O35: - | P35: - | Q35: 金田
B36: =ROW()-ROW($B$3) -> 33 | F36: 「<<」ボタン | K36: 押下した通りにページ遷移できること | M36: OK | N36: - | O36: - | P36: - | Q36: 金田
B37: =ROW()-ROW($B$3) -> 34 | D37: 事前申請タブ | E37: 表示項目設定 | J37: 任意の項目で表示項目設定する | K37: 設定どおりに一覧が最新化されること | M37: OK | N37: - | O37: - | P37: - | Q37: 金子
B38: =ROW()-ROW($B$3) -> 35 | E38: ソートボタン | F38: 申請ID | J38: 申請IDカラムのソートボタンを押下 | K38: 一覧がID順になること | M38: OK | N38: - | O38: - | P38: - | Q38: 金子
B39: =ROW()-ROW($B$3) -> 36 | E39: 申請状況 | F39: 未申請 | K39: 未申請ステータスになること | M39: OK | N39: - | O39: - | P39: - | Q39: 北川 | R39: （金子）実施方法不明 →事前申請を作成し、保存して申請するを押下後、事前申請ダイアログで申請せずにダイアログを閉じる
B40: =ROW()-ROW($B$3) -> 37 | F40: 承認待ち(事前申請) | K40: 承認待ち(事前申請)になること | M40: OK | N40: - | O40: - | P40: - | Q40: 金子
B41: =ROW()-ROW($B$3) -> 38 | F41: 取下げ(事前申請) | K41: 取下げ(事前申請)になること | M41: OK | N41: - | O41: - | P41: - | Q41: 金子
...

Sheet 承認
L2: Win11/ Chrome | M2: Win11/ Edge | N2: Win11/ Firefox | O2: Mac/ Safari
B3: No | C3: 画面 | D3: 確認対象 | E3: 項目3 | F3: 項目4 | G3: 項目5 | H3: 項目6 | I3: テスト実行手順 | J3: 期待値 | K3: 備考 | L3: TK+TI+TD | M3: TI+TD | N3: TI+TD | O3: TK単体 | P3: 実行者 | Q3: 実行備考 | R3: 起票JIRA No
B4: =ROW()-ROW($B$3) -> 1 | C4: 承認一覧 | D4: ファイル出力確認 | E4: 経費精算タブ | F4: この条件で会計データ作成を開始ボタン | G4: メールで送信 | J4: メール通知されること | L4: OK | M4: - | N4: - | O4: OK | P4: 金田
B5: =ROW()-ROW($B$3) -> 2 | G5: ダウンロード | J5: 指定したファイルでダウンロードされること | L5: OK | M5: - | N5: - | O5: OK | P5: 金田
B6: =ROW()-ROW($B$3) -> 3 | E6: 事前申請タブ | F6: この条件でファイル出力するボタン | G6: 最新の出力ファイルを開始 | J6: 最新のファイルがダウンロードできること | L6: OK | M6: - | N6: - | O6: - | P6: 金田 | Q6: ファイル出力を行おうとした際にエラーで出力が出来ない | R6: FA-98 ⇒修正確認済
B7: =ROW()-ROW($B$3) -> 4 | E7: 汎用申請タブ | F7: この条件でファイル出力するボタン | J7: 最新のファイルがダウンロードできること | L7: OK | M7: - | N7: - | O7: - | P7: 金田
B8: =ROW()-ROW($B$3) -> 5 | E8: 支払依頼申請タブ | F8: この条件で会計データ作成を開始ボタン | G8: ダウンロード | J8: 指定したファイルでダウンロードされること | L8: OK | M8: OK | N8: OK | O8: - | P8: 金田
B9: =ROW()-ROW($B$3) -> 6 | E9: 一括支払依頼申請タブ | F9: ボタン非表示確認 | J9: ファイル出力ボタンが非表示 | L9: OK | M9: OK | N9: OK | O9: - | P9: 金田
B10: =ROW()-ROW($B$3) -> 7 | E10: 稟議申請タブ | F10: ボタン非表示確認 | J10: ファイル出力ボタンが非表示 | L10: OK | M10: - | N10: - | O10: - | P10: 北川 | Q10: 項目修正依頼中 →仕様変更により表示される
B11: =ROW()-ROW($B$3) -> 8 | D11: 検索条件を指定 | E11: 経費精算タブ | I11: 任意の項目で検索 | J11: 検索通りに絞り込めること | L11: OK | M11: - | N11: - | O11: - | P11: 金田
B12: =ROW()-ROW($B$3) -> 9 | E12: 事前申請タブ | I12: 任意の項目で検索 | J12: 検索通りに絞り込めること | L12: OK | M12: - | N12: - | O12: - | P12: 金田
B13: =ROW()-ROW($B$3) -> 10 | E13: 汎用申請タブ | I13: 任意の項目で検索 | J13: 検索通りに絞り込めること | L13: OK | M13: - | N13: - | O13: - | P13: 金田
B14: =ROW()-ROW($B$3) -> 11 | E14: 支払依頼申請タブ | I14: 任意の項目で検索 | J14: 検索通りに絞り込めること | L14: OK | M14: - | N14: - | O14: - | P14: 金田
B15: =ROW()-ROW($B$3) -> 12 | E15: 稟議申請タブ | I15: 任意の項目で検索 | J15: 検索通りに絞り込めること | L15: OK | M15: - | N15: - | O15: - | P15: 金田
B16: =ROW()-ROW($B$3) -> 13 | E16: 一括支払依頼申請 | I16: 任意の項目で検索 | J16: 検索通りに絞り込めること | L16: OK | M16: - | N16: - | O16: - | P16: 金田
B17: =ROW()-ROW($B$3) -> 14 | D17: 検索条件をリセット | I17: 検索条件をリセットを押下 | J17: リセットできること | L17: OK | M17: - | N17: - | O17: - | P17: 金田
B18: =ROW()-ROW($B$3) -> 15 | D18: 経費精算タブ | E18: 一括承認 | I18: 前提：システム設定 > 申請フロー で一括承認設定をONにする 1.承認一覧で、任意のデータにチェックをいれて、一括承認ボタンを押下 | J18: 一括承認できること | L18: OK | M18: - | N18: - | O18: - | P18: 金田
B19: =ROW()-ROW($B$3) -> 16 | E19: 表示項目設定 | I19: 任意の項目で表示項目設定する | J19: 設定どおりに一覧が最新化されること | L19: OK | M19: - | N19: - | O19: - | P19: 金田
B20: =ROW()-ROW($B$3) -> 17 | E20: ソートボタン | F20: 申請ID | I20: 申請IDカラムのソートボタンを押下 | J20: 一覧がID順になること | L20: OK | M20: - | N20: - | O20: - | P20: 金田
B21: =ROW()-ROW($B$3) -> 18 | F21: 申請種別 | I21: 1.申請種別カラムを押下 2.経費申請、精算(仮払以外)、精算(仮払)の✅を外す | J21: 外したものが一覧から外れること | L21: OK | M21: - | N21: - | O21: - | P21: 金子
B22: =ROW()-ROW($B$3) -> 19 | E22: 申請状況 | F22: 承認待ち | I22: 1.申請者：経費申請する 2.承認者：承認一覧を確認 | J22: 承認待ちステータスになること | L22: OK | M22: - | N22: - | O22: - | P22: 金田
B23: =ROW()-ROW($B$3) -> 20 | F23: 承認済み | I23: 1.申請者：経費申請する 2.承認者：承認する 3.承認者：承認一覧を確認 | J23: 承認待ちステータスになること | L23: OK | M23: - | N23: - | O23: - | P23: 金田
B24: =ROW()-ROW($B$3) -> 21 | F24: 承認見込み | I24: 1.申請者：経費申請する 2.承認者：差し戻す 3.承認者：申請一覧を確認 | J24: 承認見込みステータスになること | L24: OK | M24: - | N24: - | O24: - | P24: 北川 | Q24: 左記手順では承認見込みステータスにならない場合がある。 第２承認で第１承認者に差し戻した際、承認見込みステータスになることを確認 ↑本番と見比べたらOKつけてよいです！（富田）
B25: =ROW()-ROW($B$3) -> 22 | E25: 出力ボタン | F25: 精算申請書出力 | J25: 精算申請書をダウンロードできること | L25: OK | M25: - | N25: - | O25: - | P25: 金田
B26: =ROW()-ROW($B$3) -> 23 | F26: 会計データ出力 | G26: 任意のフォーマット | H26: メールで送信 | J26: メールで通知されること | L26: OK | M26: - | N26: - | O26: - | P26: 金田
B27: =ROW()-ROW($B$3) -> 24 | H27: ダウンロード | J27: 会計データが出力されること | L27: OK | M27: - | N27: - | O27: - | P27: 金田
B28: =ROW()-ROW($B$3) -> 25 | E28: 削除ボタン | J28: 削除できること | L28: OK | M28: - | N28: - | O28: - | P28: 金田
B29: =ROW()-ROW($B$3) -> 26 | E29: 表示件数 | J29: 表示件数を変更できること | L29: OK | M29: - | N29: - | O29: - | P29: 金田
B30: =ROW()-ROW($B$3) -> 27 | E30: ページネーション | F30: 数字のボタン | J30: 押下した通りにページ遷移できること | L30: OK | M30: - | N30: - | O30: - | P30: 金田
B31: =ROW()-ROW($B$3) -> 28 | F31: 「>」ボタン | J31: 押下した通りにページ遷移できること | L31: OK | M31: - | N31: - | O31: - | P31: 金田
B32: =ROW()-ROW($B$3) -> 29 | F32: 「<」ボタン | J32: 押下した通りにページ遷移できること | L32: OK | M32: - | N32: - | O32: - | P32: 金田
B33: =ROW()-ROW($B$3) -> 30 | F33: 「>>」ボタン | J33: 押下した通りにページ遷移できること | L33: OK | M33: - | N33: - | O33: - | P33: 金田
B34: =ROW()-ROW($B$3) -> 31 | F34: 「<<」ボタン | J34: 押下した通りにページ遷移できること | L34: OK | M34: - | N34: - | O34: - | P34: 金田
B35: =ROW()-ROW($B$3) -> 32 | D35: 事前申請タブ | E35: 表示項目設定 | I35: 任意の項目で表示項目設定する | J35: 設定どおりに一覧が最新化されること | L35: OK | M35: - | N35: - | O35: - | P35: 金田
B36: =ROW()-ROW($B$3) -> 33 | E36: ソートボタン | F36: 申請ID | I36: 申請IDカラムのソートボタンを押下 | J36: 一覧がID順になること | L36: OK | M36: - | N36: - | O36: - | P36: 金田
B37: =ROW()-ROW($B$3) -> 34 | E37: 申請状況 | F37: 承認待ち(事前申請) | I37: 1.申請者：事前申請する 2.承認者：承認一覧を確認 | J37: 承認待ち(事前申請)になること | L37: OK | M37: - | N37: - | O37: - | P37: 金田
B38: =ROW()-ROW($B$3) -> 35 | F38: 未精算 | I38: 1.申請者：事前申請する 2.承認者：承認する 3.承認者：承認一覧を確認 ※検索条件で"あなたの承認状況"を「承認済み」にする | J38: 申請状況が 未精算 になること | L38: OK | M38: - | N38: - | O38: - | P38: 金田
B39: =ROW()-ROW($B$3) -> 36 | F39: 承認待ち(精算申請) | I39: 1.申請者：事前申請する 2.承認者：承認する 3.申請者：精算申請する 4.承認者：承認一覧を確認 ※検索条件で"あなたの承認状況"を「承認済み」にする | J39: 申請状況が 承認待ち(精算申請) になること | L39: OK | M39: - | N39: - | O39: - | P39: 金子
B40: =ROW()-ROW($B$3) -> 37 | F40: 精算済み | I40: 1.申請者：事前申請する 2.承認者：承認する 3.申請者：精算申請する 4.承認者：承認一覧を確認 ※検索条件で"あなたの承認状況"を「承認済み」にする | J40: 申請状況が 未精算になること になること | L40: OK | M40: - | N40: - | O40: - | P40: 金子
B41: =ROW()-ROW($B$3) -> 38 | E41: 出力ボタン | F41: 事前申請書出力 | J41: 精算申請書をダウンロードできること | L41: OK | M41: - | N41: - | O41: - | P41: 金田
...

Sheet 経費
N2: Win11/ Chrome | O2: Win11/ Edge | P2: Win11/ Firefox | Q2: MacOS/ Safari
B3: No | C3: 画面 | D3: 確認対象 | E3: 詳細 | K3: テスト実行手順 | L3: 期待値 | M3: 備考 | N3: TK+TI+TD | O3: TK+TI+TD | P3: TK単体 | Q3: TK単体 | R3: 実行者 | S3: 実行備考 | T3: 起票JIRA No
B4: =ROW()-ROW($B$3) -> 1 | C4: 経費一覧 | D4: 経費を登録する | E4: 手入力 | K4: 経費を登録する＞手入力を押下する 任意の設定で経費を登録する | L4: 指定した経費が作成できること 保存した経費に入力した内容が反映されていること | M4: 新規ボタンと共通なので項目は省略 | N4: OK | O4: - | P4: - | Q4: - | R4: 金田
B5: =ROW()-ROW($B$3) -> 2 | C5: 経費一覧 | E5: 交通費入力 | K5: 経費を登録する＞交通費入力を押下する 任意の設定で経費を登録する | L5: - | M5: 新規ボタンと共通なので項目は省略 | N5: OK | O5: - | P5: - | Q5: - | R5: 金田
B6: =ROW()-ROW($B$3) -> 3 | C6: 経費一覧 | E6: 日当 | K6: 経費を登録する＞日当を押下する 任意の設定で経費を登録する | L6: - | M6: 新規ボタンと共通なので項目は省略 | N6: OK | O6: - | P6: - | Q6: - | R6: 金田
B7: =ROW()-ROW($B$3) -> 4 | C7: 経費一覧 | E7: 自動入力 | K7: 経費を登録する＞自動入力を押下する | L7: 自動入力新規登録画面に遷移すること | M7: 新規ボタンと共通なので項目は省略 | N7: OK | O7: - | P7: - | Q7: - | R7: 金田
B8: =ROW()-ROW($B$3) -> 5 | C8: 経費一覧 | D8: 検索条件 | E8: 会社全体 | K8: 左記の検索条件を設定して検索 | L8: 条件に基づいた検索結果が表示されること | N8: OK | O8: - | P8: - | Q8: - | R8: 金田
B9: =ROW()-ROW($B$3) -> 6 | C9: 経費一覧 | E9: 削除済み | G9: - | H9: - | K9: 同上 | L9: 同上 | N9: OK | O9: - | P9: - | Q9: - | R9: 金田
B10: =ROW()-ROW($B$3) -> 7 | C10: 経費一覧 | E10: 従業員 | G10: - | H10: - | K10: 同上 | L10: 同上 | N10: OK | O10: - | P10: - | Q10: - | R10: 金田
B11: =ROW()-ROW($B$3) -> 8 | C11: 経費一覧 | E11: 申請ID | G11: - | H11: - | K11: 同上 | L11: 同上 | N11: OK | O11: - | P11: - | Q11: - | R11: 金田
B12: =ROW()-ROW($B$3) -> 9 | C12: 経費一覧 | E12: 利用日 | F12: 〇〇から | G12: - | H12: - | K12: 同上 | L12: 同上 | N12: OK | O12: - | P12: - | Q12: - | R12: 金田
B13: =ROW()-ROW($B$3) -> 10 | C13: 経費一覧 | F13: 〇〇まで | G13: - | H13: - | K13: 同上 | L13: 同上 | N13: OK | O13: - | P13: - | Q13: - | R13: 金田
B14: =ROW()-ROW($B$3) -> 11 | C14: 経費一覧 | F14: 空白検索 | G14: - | H14: - | K14: 同上 | L14: 同上 | N14: OK | O14: - | P14: - | Q14: - | R14: 金田
B15: =ROW()-ROW($B$3) -> 12 | C15: 経費一覧 | E15: 支払先 | G15: - | H15: - | K15: 同上 | L15: 同上 | N15: OK | O15: - | P15: - | Q15: - | R15: 金田
B16: =ROW()-ROW($B$3) -> 13 | C16: 経費一覧 | F16: 空白検索 | G16: - | H16: - | K16: 同上 | L16: 同上 | N16: OK | O16: - | P16: - | Q16: - | R16: 金田
B17: =ROW()-ROW($B$3) -> 14 | C17: 経費一覧 | E17: 金額 | F17: 〇〇から | G17: - | H17: - | K17: 同上 | L17: 同上 | N17: OK | O17: - | P17: - | Q17: - | R17: 金田
B18: =ROW()-ROW($B$3) -> 15 | C18: 経費一覧 | F18: 〇〇まで | G18: - | H18: - | K18: 同上 | L18: 同上 | N18: OK | O18: - | P18: - | Q18: - | R18: 金田
B19: =ROW()-ROW($B$3) -> 16 | C19: 経費一覧 | F19: 空白検索 | G19: - | H19: - | K19: 同上 | L19: 同上 | N19: OK | O19: - | P19: - | Q19: - | R19: 金田
B20: =ROW()-ROW($B$3) -> 17 | C20: 経費一覧 | E20: 経費科目 | G20: - | H20: - | K20: 同上 | L20: 同上 | N20: OK | O20: - | P20: - | Q20: - | R20: 金田
B21: =ROW()-ROW($B$3) -> 18 | C21: 経費一覧 | E21: 所属部署 | G21: - | H21: - | K21: 同上 | L21: 同上 | N21: OK | O21: - | P21: - | Q21: - | R21: 金田
B22: =ROW()-ROW($B$3) -> 19 | C22: 経費一覧 | F22: 下位部署を含む | G22: - | H22: - | K22: 同上 | L22: 同上 | N22: OK | O22: - | P22: - | Q22: - | R22: 金田
B23: =ROW()-ROW($B$3) -> 20 | C23: 経費一覧 | E23: 精算区分 | F23: 精算対象 | G23: - | H23: - | K23: 同上 | L23: 同上 | N23: OK | O23: - | P23: - | Q23: - | R23: 金田
B24: =ROW()-ROW($B$3) -> 21 | C24: 経費一覧 | F24: 精算対象外 | G24: - | H24: - | K24: 同上 | L24: 同上 | N24: OK | O24: - | P24: - | Q24: - | R24: 金田
B25: =ROW()-ROW($B$3) -> 22 | C25: 経費一覧 | E25: コーポレートカード利用 | F25: あり | G25: - | H25: - | K25: 同上 | L25: 同上 | M25: dev環境で行う | N25: OK | O25: - | P25: - | Q25: - | R25: 本橋
B26: =ROW()-ROW($B$3) -> 23 | C26: 経費一覧 | F26: なし | G26: - | H26: - | K26: 同上 | L26: 同上 | N26: OK | O26: - | P26: - | Q26: - | R26: 本橋
B27: =ROW()-ROW($B$3) -> 24 | C27: 経費一覧 | E27: 原本確認 | F27: 確認済み | K27: 同上 | L27: 同上 | M27: PLP契約がないと表示されない | N27: OK | O27: - | P27: - | Q27: - | R27: 行田 | S27: 同上
B28: =ROW()-ROW($B$3) -> 25 | C28: 経費一覧 | F28: 確認済みステータス更新 | K28: 同上 | L28: 同上 | N28: OK | O28: - | P28: - | Q28: - | R28: 行田 | S28: 同上
B29: =ROW()-ROW($B$3) -> 26 | C29: 経費一覧 | F29: 未確認 | K29: 同上 | L29: 同上 | N29: OK | O29: - | P29: - | Q29: - | R29: 行田 | S29: 同上
B30: =ROW()-ROW($B$3) -> 27 | C30: 経費一覧 | F30: 不要 | K30: 同上 | L30: 同上 | N30: OK | O30: - | P30: - | Q30: - | R30: 行田 | S30: 同上
B31: =ROW()-ROW($B$3) -> 28 | C31: 経費一覧 | E31: 出力ID | G31: - | H31: - | K31: 同上 | L31: 同上 | M31: 適当なIDで検索して検索結果が出なければOK | N31: OK | O31: - | P31: - | Q31: - | R31: 金田
B32: =ROW()-ROW($B$3) -> 29 | C32: 経費一覧 | E32: 電子領収書区分 | F32: 電子領収書 | G32: - | H32: - | K32: 同上 | L32: 同上 | N32: OK | O32: - | P32: - | Q32: - | R32: 金田
B33: =ROW()-ROW($B$3) -> 30 | C33: 経費一覧 | F33: 電子領収書以外 | K33: 同上 | L33: 同上 | N33: OK | O33: - | P33: - | Q33: - | R33: 金田
B34: =ROW()-ROW($B$3) -> 31 | C34: 経費一覧 | E34: 汎用マスタ | F34: コード | G34: - | H34: - | K34: 同上 | L34: 同上 | N34: OK | O34: - | P34: - | Q34: - | R34: 金田
B35: =ROW()-ROW($B$3) -> 32 | C35: 経費一覧 | F35: 名称 | K35: 同上 | L35: 同上 | N35: OK | O35: - | P35: - | Q35: - | R35: 金田
B36: =ROW()-ROW($B$3) -> 33 | C36: 経費一覧 | E36: 登録番号 | G36: - | H36: - | K36: 同上 | L36: 同上 | N36: OK | O36: - | P36: - | Q36: - | R36: 金田
B37: =ROW()-ROW($B$3) -> 34 | C37: 経費一覧 | F37: 空白検索 | G37: - | H37: - | K37: 同上 | L37: 同上 | N37: OK | O37: - | P37: - | Q37: - | R37: 金田
B38: =ROW()-ROW($B$3) -> 35 | C38: 経費一覧 | E38: 適格請求書の取り扱い | F38: あり | G38: - | H38: - | K38: 同上 | L38: 同上 | N38: OK | O38: - | P38: - | Q38: - | R38: 金田
B39: =ROW()-ROW($B$3) -> 36 | C39: 経費一覧 | F39: なし | G39: - | H39: - | K39: 同上 | L39: 同上 | N39: OK | O39: - | P39: - | Q39: - | R39: 金田
B40: =ROW()-ROW($B$3) -> 37 | C40: 経費一覧 | E40: ステータス | F40: 未申請 | G40: - | H40: - | K40: 同上 | L40: 同上 | N40: OK | O40: - | P40: - | Q40: - | R40: 金田
B41: =ROW()-ROW($B$3) -> 38 | C41: 経費一覧 | F41: 下書き保存中の申請を含める | G41: - | H41: - | K41: 同上 | L41: 同上 | N41: OK | O41: - | P41: - | Q41: - | R41: 金田
...

Sheet カード明細
N2: Chrome | O2: Win11/ Edge | P2: Win11/ Firefox | Q2: Win11/ Safari
B3: No | C3: 画面 | D3: 確認対象 | E3: 詳細 | K3: テスト実行手順 | L3: 期待値 | M3: 備考 | N3: TK+TI+TD | O3: TK+TI+TD | P3: TK単体 | Q3: TK単体 | R3: 実行者 | S3: 実行備考 | T3: 起票JIRA No
B4: =ROW()-ROW($B$3) -> 1 | C4: カード明細 | D4: 連携カード・サービス一覧 | E4: 表示件数 | K4: 1.連携口座・カード一覧を開く 2.カード一覧の表示件数を変更する | L4: 任意の表示件数に変更できること | N4: OK | O4: OK | P4: - | Q4: - | R4: 北川
B5: =ROW()-ROW($B$3) -> 2 | C5: カード明細 | D5: 連携カード・サービス一覧 | E5: ページネーション | F5: ページ指定 | K5: 任意のページを押下する | L5: 指定したページに移動すること | N5: OK | O5: - | P5: - | Q5: - | R5: 北川
B6: =ROW()-ROW($B$3) -> 3 | C6: カード明細 | D6: 連携カード・サービス一覧 | F6: > | K6: >を押下する | L6: 指定したページに移動すること | N6: OK | O6: - | P6: - | Q6: - | R6: 北川
B7: =ROW()-ROW($B$3) -> 4 | C7: カード明細 | D7: 連携カード・サービス一覧 | F7: >> | K7: >>を押下する | L7: 最後尾のページに移動すること | N7: OK | O7: - | P7: - | Q7: - | R7: 北川
B8: =ROW()-ROW($B$3) -> 5 | C8: カード明細 | D8: 連携カード・サービス一覧 | F8: < | K8: <を押下する | L8: 指定したページに移動すること | N8: OK | O8: - | P8: - | Q8: - | R8: 北川
B9: =ROW()-ROW($B$3) -> 6 | C9: カード明細 | D9: 連携カード・サービス一覧 | F9: << | K9: <<を押下する | L9: 先頭のページに移動すること | N9: OK | O9: - | P9: - | Q9: - | R9: 北川
B10: =ROW()-ROW($B$3) -> 7 | C10: カード明細 | D10: 連携カード・サービス一覧 | E10: 名前 | K10: 任意のカードの名前を押下する 編集する | L10: 編集できることを確認 | N10: OK | O10: - | P10: - | Q10: - | R10: 北川
B11: =ROW()-ROW($B$3) -> 8 | C11: カード明細 | D11: 連携カード・サービス一覧 | E11: 保存 | K11: 任意のカードの名前を押下する 保存する | L11: 任意のカードの名称が変更できること | N11: OK | O11: - | P11: - | Q11: - | R11: 北川
B12: =ROW()-ROW($B$3) -> 9 | C12: カード明細 | D12: 連携カード・サービス一覧 | E12: 編集 | K12: 任意のカードの編集アイコンを押下する | L12: 任意のカードの編集画面に遷移すること | N12: OK | O12: - | P12: - | Q12: - | R12: 北川
B13: =ROW()-ROW($B$3) -> 10 | C13: カード明細 | D13: 連携カード・サービス一覧 | E13: 削除 | K13: 任意のカードの削除アイコンを押下する | L13: 任意のカードが削除されること | N13: OK | O13: - | P13: - | Q13: - | R13: 北川
B14: =ROW()-ROW($B$3) -> 11 | C14: カード明細 | D14: 連携カード・サービス一覧 | E14: 再取得 | K14: 任意のカードの再取得アイコンを押下する | L14: カードの情報が再取得されること 最終更新の横の日付時間が更新されること | N14: OK | O14: - | P14: - | Q14: - | R14: 北川 | S14: 要カードアカウント 交通系IC（物理）では不可
B15: =ROW()-ROW($B$3) -> 12 | C15: カード明細 | D15: 連携カード・サービス一覧 | E15: 最終更新日 | K15: 利用履歴の取得に成功したカードの最終更新日を確認する | L15: 最終更新日が記載されていること | N15: OK | O15: - | P15: - | Q15: - | R15: 北川
B16: =ROW()-ROW($B$3) -> 13 | C16: カード明細 | D16: 連携カード・サービス一覧 | E16: アラート | F16: 警告アイコン | K16: 連携口座・カードのログインに失敗する アラートアイコンを確認する アイコンにマウスオーバーする | L16: 該当のアラートアイコンが表示されること 「ログインに失敗しました」の文字が表示されること ログインに成功するとアイコンが消えること | N16: OK | O16: OK | P16: - | Q16: - | R16: 北川 | S16: 要カードアカウント
B17: =ROW()-ROW($B$3) -> 14 | C17: カード明細 | D17: 連携カード・サービス一覧 | F17: お知らせアイコン | K17: 連携口座・カードの画像認証に失敗する アラートアイコンを確認する アイコンにマウスオーバーする | L17: 該当のアラートアイコンが表示されること 「一定時間内に画像認証に完了しませんでした。再取得するともう一度画像認証を行うことができます」の文字が表示されること 画像認証に成功するとアイコンが消えること | N17: OK | O17: OK | P17: - | Q17: - | R17: 北川
B18: =ROW()-ROW($B$3) -> 15 | C18: カード明細 | D18: 連携カード・サービス一覧 | F18: 取得中アイコン | K18: 連携口座・カードを登録して利用履歴を取得するまでにアイコンを確認する アイコンにマウスオーバーする | L18: 該当のアイコンが表示されること 「ただいま取得中です」が表示されること | N18: OK | O18: OK | P18: - | Q18: - | R18: 北川
B19: =ROW()-ROW($B$3) -> 16 | C19: カード明細 | D19: 利用履歴 | E19: 経費を登録（上画面） | F19: 経費 | G19: 経費科目 | K19: 1.任意の経費履歴を選択し、経費登録モーダルを開く 2.左記の項目を編集する 3.経費を作成する 4.左記の項目を確認する | L19: カードの利用履歴を反映した経費が作成されること 左記の編集した編集した項目が反映されていること | M19: 経費登録すると、登録に使用した内容は利用履歴から削除される | N19: OK | O19: - | P19: - | Q19: - | R19: 北川 | S19: 利用履歴を用意できる実アカウントが必要 今回はVEC実施時のテナントとダミーデータを使用
B20: =ROW()-ROW($B$3) -> 17 | C20: カード明細 | D20: 利用履歴 | F20: 経費 | G20: 事前申請名 | K20: 同上 | L20: 同上 | N20: OK | O20: - | P20: - | Q20: - | R20: 北川
B21: =ROW()-ROW($B$3) -> 18 | C21: カード明細 | D21: 利用履歴 | F21: 経費 | G21: プロジェクト | K21: 同上 | L21: 同上 | N21: OK | O21: - | P21: - | Q21: - | R21: 北川
B22: =ROW()-ROW($B$3) -> 19 | C22: カード明細 | D22: 利用履歴 | F22: 経費 | G22: 所属部署 | K22: 同上 | L22: 同上 | N22: OK | O22: - | P22: - | Q22: - | R22: 北川
B23: =ROW()-ROW($B$3) -> 20 | C23: カード明細 | D23: 利用履歴 | F23: 経費 | G23: 費用負担部署 | K23: 同上 | L23: 同上 | N23: OK | O23: - | P23: - | Q23: - | R23: 北川
B24: =ROW()-ROW($B$3) -> 21 | C24: カード明細 | D24: 利用履歴 | F24: 経費 | G24: メモ | K24: 同上 | L24: 同上 | N24: OK | O24: - | P24: - | Q24: - | R24: 北川
B25: =ROW()-ROW($B$3) -> 22 | C25: カード明細 | D25: 利用履歴 | F25: 交通費 | G25: 経費科目 | K25: 同上 | L25: 同上 | N25: OK | O25: - | P25: - | Q25: - | R25: 北川
B26: =ROW()-ROW($B$3) -> 23 | C26: カード明細 | D26: 利用履歴 | F26: 交通費 | G26: 事前申請名 | K26: 同上 | L26: 同上 | N26: OK | O26: - | P26: - | Q26: - | R26: 北川
B27: =ROW()-ROW($B$3) -> 24 | C27: カード明細 | D27: 利用履歴 | F27: 交通費 | G27: プロジェクト | K27: 同上 | L27: 同上 | N27: OK | O27: - | P27: - | Q27: - | R27: 北川
B28: =ROW()-ROW($B$3) -> 25 | C28: カード明細 | D28: 利用履歴 | F28: 交通費 | G28: 所属部署 | K28: 同上 | L28: 同上 | N28: OK | O28: - | P28: - | Q28: - | R28: 北川
B29: =ROW()-ROW($B$3) -> 26 | C29: カード明細 | D29: 利用履歴 | F29: 交通費 | G29: 費用負担部署 | K29: 同上 | L29: 同上 | N29: OK | O29: - | P29: - | Q29: - | R29: 北川
B30: =ROW()-ROW($B$3) -> 27 | C30: カード明細 | D30: 利用履歴 | F30: 交通費 | G30: メモ | K30: 同上 | L30: 同上 | N30: OK | O30: - | P30: - | Q30: - | R30: 北川
B31: =ROW()-ROW($B$3) -> 28 | C31: カード明細 | D31: 利用履歴 | E31: 履歴を削除（上画面） | K31: 選択した履歴を削除する | L31: 選択した履歴が削除されること | N31: OK | O31: - | P31: - | Q31: - | R31: 北川
B32: =ROW()-ROW($B$3) -> 29 | C32: カード明細 | D32: 利用履歴 | E32: 経費を登録（画面右） | F32: 経費 | G32: 経費科目 | K32: 1.任意の交通費履歴を選択し、経費登録モーダルを開く 2.左記の項目を編集する 3.経費を作成する 4.左記の項目を確認する | L32: カードの利用履歴を反映した経費が作成されること 左記の編集した編集した項目が反映されていること | N32: OK | O32: - | P32: - | Q32: - | R32: 北川
B33: =ROW()-ROW($B$3) -> 30 | C33: カード明細 | D33: 利用履歴 | F33: 経費 | G33: 事前申請名 | K33: 同上 | L33: 同上 | N33: OK | O33: - | P33: - | Q33: - | R33: 北川
B34: =ROW()-ROW($B$3) -> 31 | C34: カード明細 | D34: 利用履歴 | F34: 経費 | G34: プロジェクト | K34: 同上 | L34: 同上 | N34: OK | O34: - | P34: - | Q34: - | R34: 北川
B35: =ROW()-ROW($B$3) -> 32 | C35: カード明細 | D35: 利用履歴 | F35: 経費 | G35: 所属部署 | K35: 同上 | L35: 同上 | N35: OK | O35: - | P35: - | Q35: - | R35: 北川
B36: =ROW()-ROW($B$3) -> 33 | C36: カード明細 | D36: 利用履歴 | F36: 経費 | G36: 費用負担部署 | K36: 同上 | L36: 同上 | N36: OK | O36: - | P36: - | Q36: - | R36: 北川
B37: =ROW()-ROW($B$3) -> 34 | C37: カード明細 | D37: 利用履歴 | F37: 経費 | G37: メモ | K37: 同上 | L37: 同上 | N37: OK | O37: - | P37: - | Q37: - | R37: 北川
B38: =ROW()-ROW($B$3) -> 35 | C38: カード明細 | D38: 利用履歴 | F38: 交通費 | G38: 経費科目 | K38: 同上 | L38: 同上 | N38: OK | O38: - | P38: - | Q38: - | R38: 北川
B39: =ROW()-ROW($B$3) -> 36 | C39: カード明細 | D39: 利用履歴 | F39: 交通費 | G39: 事前申請名 | K39: 同上 | L39: 同上 | N39: OK | O39: - | P39: - | Q39: - | R39: 北川
B40: =ROW()-ROW($B$3) -> 37 | C40: カード明細 | D40: 利用履歴 | F40: 交通費 | G40: プロジェクト | K40: 同上 | L40: 同上 | N40: OK | O40: - | P40: - | Q40: - | R40: 北川
B41: =ROW()-ROW($B$3) -> 38 | C41: カード明細 | D41: 利用履歴 | F41: 交通費 | G41: 所属部署 | K41: 同上 | L41: 同上 | N41: OK | O41: - | P41: - | Q41: - | R41: 北川
...

Sheet 仮払
N2: Win11/ Chrome | O2: Win11/ edge | P2: Win11/ Firefox | Q2: Win11/ Safari
B3: No | C3: 画面 | D3: 確認対象 | E3: 詳細 | K3: テスト実行手順 | L3: 期待値 | M3: 備考 | N3: TK+TI+TD | O3: TK+TI+TD | P3: TK単体 | Q3: TK単体 | R3: 実行者 | S3: 実行備考 | T3: 起票JIRA No
B4: =ROW()-ROW($B$3) -> 1 | C4: 仮払一覧画面 | D4: タブ | E4: 仮払待ち | K4: 左記のタブを確認する タブを押下する | L4: タブの横に表示件数が表示されること 表示される事前申請の種類が変更されること | N4: OK | O4: OK | P4: OK | Q4: OK | R4: 行田 北川(Mac)
B5: =ROW()-ROW($B$3) -> 2 | C5: 仮払一覧画面 | E5: 未精算 | K5: 同上 | L5: 同上 | N5: OK | O5: OK | P5: OK | Q5: OK | R5: 行田 北川(Mac)
B6: =ROW()-ROW($B$3) -> 3 | C6: 仮払一覧画面 | E6: 仮払差額返金待ち | K6: 同上 | L6: 同上 | N6: OK | O6: OK | P6: OK | Q6: OK | R6: 行田 北川(Mac)
