Workbook

Sheet 運用ルール
B2: ■各シートの説明
F4: 設計者 | G4: レビュアー | H4: 実行者 | I4: 管理者 (サブリーダー) | J4: 用途
C5: シート名 | D5: 観点 | F5: 〇 | G5: 〇 | J5: テストケース作成前の情報整理する場所。レビュアーはこのシートを見て、網羅性が担保されているか等、レビューする。
D6: テストケース | F6: 〇 | G6: 〇 | H6: 〇 | J6: テストケース作成場所。観点シートでまとめた内容を元に作成。シート名は臨機応変に変更したり増やしたりしてOK。
D7: 進捗 | F7: 〇 | G7: 〇 | H7: 〇 | J7: テストケースの進捗度合いを測るシート。バーンアップは、予定通り進捗が進んでいるか測る指標。
D8: チェック表 | I8: 〇 | J8: QAプロセス全般のチェックリスト。
F9: 〇=利用者
B12: ■設計者のルール
B13: ・観点シート
C14: 下記を参考にまとめる
C15: テスト観点の補助
C16: テスト技法について
C17: 過去テストの例：
C18: テスト項目書_事前申請の更新で、旅費申請のON/OFFと事前申請項目の変更を同時に行うと、事前申請項目の更新内容が反映されない
C21: 設計例
D22: 同値分割法： | E22: https://docs.google.com/spreadsheets/d/1stgUWYgVCMKF_rU1uwI8Lsjbtay60kwjXhUexbCR6vA/edit?gid=0#gid=0
D23: 境界値分析： | E23: https://docs.google.com/spreadsheets/d/1flvqVgReHsZYZa-aAdE46ixwuvpJ_Regafid6LaLrrk/edit?gid=0#gid=0
D24: ペアワイズ法：
D25: デシジョンテーブル：
D26: 状態遷移テスト：
B29: ・テストケースシート
C30: 全体の表現 | D30: ：我流の単語は使わない。要件ページやPRDに沿った表現に統一する
C31: "手順"列 | D31: ：極力省かない、
C32: "期待値"列 | D32: ：曖昧に書かない。「正常であること」「問題ないこと」「仕様通りであること」といった表現は書きがちだが、基本NG。
D33: 基本的に1ケースにつき、期待値は一つ。
C34: ステータス | D34: ：事前対象外については | F34: - | G34: をつける
C35: "備考"列 | D35: ：補足事項を入れる
B37: ・進捗シート
C38: 最新化する
B41: ■レビュアーのルール
B42: ・レビュアーは、特に以下を重点的に気を付けてレビューする
C43: 観点レビュー | E43: 体裁 | F43: 観点の目次を見て、一目でどんなテストをするのかが伝わる状態か
E44: 網羅性 | F44: 観点の補助の漏れがないか
F45: テスト技法が必要な観点で正しく使えているか
F46: 開発側から提示された観点が盛り込まれているか
F47: 主要観点で〇つけたものが盛り込まれているか
F48: 過去の似たテストと比べて、ケース漏れがないか
C49: ケースレビュー | E49: 体裁 | F49: 観点の目次に沿ってまとめられているか
E50: 網羅性 | F50: 観点の記載内容が漏れなく記載できているか
B53: ■実行者のルール
...

Sheet 観点
B2: 開発からの観点（requestチャンネル）
H3: 資料 | L3: Devinに観点レビュー依頼するときに埋めてください
B4: - | H4: 要件チケット： | I4: https://beartail.atlassian.net/browse/ES-6212 | L4: 対象プロダクト： | M4: ES
H5: 要件ページ： | I5: - | L5: プルリクエスト： | M5: https://github.com/TOKIUM/drwallet-worker/pull/5140
H6: QA依頼： | I6: https://beartail.slack.com/archives/C02QY42J0UE/p1769502918052619 | L6: =IF(M4="その他", "AIの観点レビューに対応していません", "")
B9: 今回のテストに盛り込むもの
B10: OS対応 | E10: 主要観点 | F10: ※詳細
B11: Windows | C11: 〇 | E11: 負荷 | F11: -
B12: Mac | C12: - | E12: 金額確認 | F12: -
E13: 時間経過 | F13: -
B14: ブラウザ対応 | E14: 高頻度 | F14: 〇
B15: Chrome | C15: 〇 | E15: 既存機能への影響 | F15: 〇
B16: Edge | C16: - | E16: 互換性 | F16: -
B17: Firefox | C17: - | E17: データ移行 | F17: -
B18: Safari | C18: - | E18: UIUX | F18: 〇
E19: セキュリティ/権限 | F19: -
E20: お客様提供ドキュメント | F20: -
E21: 統一性 | F21: -
E22: 英語化 | F22: -
E23: 外部API | F23: -
E24: 本番環境への影響(チャットボタン等) | F24: -
E25: 契約変更(プラン・オプション変更) | F25: -
B27: ■観点の目次
B29: 確認すること | E29: 画面 | H29: 確認対象 | K29: 詳細
B30: 問題の解説編集 | E30: 練習問題管理 | H30: 編集前 | I30: 表示 | K30: 「！解説を編集 解説を編集できます。」と表示されていること
I31: 編集ボタン | K31: 編集ボタンが表示されていること
I32: ┗押下 | K32: 「クリップ項目解説の編集」画面に遷移すること
I33: 連打 | K33: 連打できてしまわないこと
H34: 解説未設定 | I34: 編集ボタン | K34: 編集ボタンが表示されていないこと
E35: クリップ項目解説の編集 | H35: 表示 | I35: 画面名称 | K35: 「クリップ項目解説の編集」と表示されていること
I36: 戻るボタン | K36: ←戻るボタンが表示されていること
I37: ┗押下 | K37: 練習問題管理画面に戻ること
I38: 画像 | K38: 左画面に解説対象の画像が表示されていること
I39: 保存ボタン | K39: 「解説を保存」ボタンが表示されていること
I40: 連打 | K40: 連打できてしまわないこと
I41: 既存の解説あり | K41: 編集前の解説が表示されていること
I42: ┗なし | K42: 解説の表示がないこと
H43: 編集 | I43: 下記クリップ項目 | K43: 既存の解説を編集できること
H44: 空白 | I44: 下記クリップ項目 | K44: スペース/改行のみで編集できること
H45: 削除 | I45: 下記クリップ項目 | K45: 既存の解説を消せること
...

Sheet テストケース
B3: ※予め解説付きの問題を作成のうえ受験済みにする | K3: Win11/ Chrome
B4: No | C4: 確認すること | D4: 画面 | E4: 確認対象 | F4: 詳細 | G4: テスト実行手順 | H4: 期待値 | I4: 備考 | J4: Autify | K4: - | L4: 実行者 | M4: 実行備考 | N4: 起票JIRA No
B5: =ROW()-ROW($B$4) -> 1 | C5: 問題の解説編集 | D5: 練習問題管理 | E5: 編集前 | F5: 表示 | G5: 1.受験の済んだ問題のクリップ解答一覧タブを選択 | H5: 「！解説を編集 解説を編集できます。」と表示されていること | K5: OK | L5: 浦本
B6: =ROW()-ROW($B$4) -> 2 | F6: 編集ボタン | G6: 1.受験の済んだ問題のクリップ解答一覧タブを選択 2.F列を確認 | H6: 「解説を編集」ボタンが表示されていること | I6: 未受験でも編集はできる…次のテストで修正します | K6: OK | L6: 浦本
B7: =ROW()-ROW($B$4) -> 3 | F7: ┗押下 | G7: 同上 | H7: 「クリップ項目解説の編集」画面に遷移すること | K7: OK | L7: 浦本
F8: 連打 | G8: 1.受験の済んだ問題のクリップ解答一覧タブを選択 2.「解説を編集」ボタンを連打する | H8: 連打できてしまわないこと | K8: OK | L8: 浦本
B9: =ROW()-ROW($B$4) -> 5 | E9: 解説未設定 | F9: 編集ボタン | G9: 1.問題をアップロード後、正解回答まで作成する（解説は未設定） 2.クリップ解答一覧タブを確認 | H9: 「解説を編集」ボタンがが表示されていないこと | K9: OK | L9: 浦本 | M9: 解説未設定だと「＋解説を作成」ボタンが表示されている
B10: =ROW()-ROW($B$4) -> 6 | D10: クリップ項目解説の編集 | E10: 表示 | F10: 画面名称 | G10: 1.画面内のF列を確認 | H10: 「クリップ項目解説の編集」と表示されていること | K10: OK | L10: 浦本
B11: =ROW()-ROW($B$4) -> 7 | F11: 戻るボタン | G11: 同上 | H11: 「←戻る」が表示されていること | K11: OK | L11: 浦本
F12: ┗押下 | G12: 同上 | H12: 練習問題管理画面に戻ること | K12: OK | L12: 浦本
B13: =ROW()-ROW($B$4) -> 9 | F13: 画像 | G13: 同上 | H13: 左画面に解説対象の画像が表示されていること | K13: OK | L13: 浦本
B14: =ROW()-ROW($B$4) -> 10 | F14: 保存ボタン | G14: 同上 | H14: 「解説を保存」ボタンが表示されていること | K14: OK | L14: 浦本
F15: ┗連打 | G15: 同上 | H15: 連打できてしまわないこと | K15: OK | L15: 浦本
B16: =ROW()-ROW($B$4) -> 12 | F16: 既存の解説あり | G16: 同上 | H16: 編集前の解説が表示されていること | K16: OK | L16: 浦本
B17: =ROW()-ROW($B$4) -> 13 | F17: ┗なし | G17: 同上 | H17: 解説の表示がないこと | K17: OK | L17: 浦本
B18: =ROW()-ROW($B$4) -> 14 | E18: 編集 | F18: 発行者 | G18: 1.F列のクリップ項目の既存の解説を任意に編集 | H18: 既存の解説を編集できること | K18: OK | L18: 浦本
B19: =ROW()-ROW($B$4) -> 15 | F19: 電話番号 | G19: 同上 | H19: 同上 | K19: OK | L19: 浦本
B20: =ROW()-ROW($B$4) -> 16 | F20: 登録番号 | G20: 同上 | H20: 同上 | K20: OK | L20: 浦本
B21: =ROW()-ROW($B$4) -> 17 | F21: 銀行 | G21: 同上 | H21: 同上 | K21: OK | L21: 浦本
B22: =ROW()-ROW($B$4) -> 18 | F22: 支払期限 | G22: 同上 | H22: 同上 | K22: OK | L22: 浦本
B23: =ROW()-ROW($B$4) -> 19 | F23: 振込手数料負担者 | G23: 同上 | H23: 同上 | K23: OK | L23: 浦本
B24: =ROW()-ROW($B$4) -> 20 | F24: 繰越額＋当月額 | G24: 同上 | H24: 同上 | K24: OK | L24: 浦本
B25: =ROW()-ROW($B$4) -> 21 | F25: 10%税込み金額 | G25: 同上 | H25: 同上 | K25: OK | L25: 浦本
B26: =ROW()-ROW($B$4) -> 22 | F26: 10%消費税 | G26: 同上 | H26: 同上 | K26: OK | L26: 浦本
B27: =ROW()-ROW($B$4) -> 23 | F27: 8%税込み金額 | G27: 同上 | H27: 同上 | K27: OK | L27: 浦本
B28: =ROW()-ROW($B$4) -> 24 | F28: 8%消費税 | G28: 同上 | H28: 同上 | K28: OK | L28: 浦本
B29: =ROW()-ROW($B$4) -> 25 | F29: 0%対象金額 | G29: 同上 | H29: 同上 | K29: OK | L29: 浦本
B30: =ROW()-ROW($B$4) -> 26 | F30: 源泉徴収税額 | G30: 同上 | H30: 同上 | K30: OK | L30: 浦本
B31: =ROW()-ROW($B$4) -> 27 | E31: 空白 | F31: 発行者 | G31: 1.F列のクリップ項目の既存の解説を文字無しでスペース/改行する | H31: スペース/改行のみで編集できること | K31: OK | L31: 浦本
B32: =ROW()-ROW($B$4) -> 28 | F32: 電話番号 | G32: 同上 | H32: 同上 | K32: OK | L32: 浦本
B33: =ROW()-ROW($B$4) -> 29 | F33: 登録番号 | G33: 同上 | H33: 同上 | K33: OK | L33: 浦本
B34: =ROW()-ROW($B$4) -> 30 | F34: 銀行 | G34: 同上 | H34: 同上 | K34: OK | L34: 浦本
B35: =ROW()-ROW($B$4) -> 31 | F35: 支払期限 | G35: 同上 | H35: 同上 | K35: OK | L35: 浦本
B36: =ROW()-ROW($B$4) -> 32 | F36: 振込手数料負担者 | G36: 同上 | H36: 同上 | K36: OK | L36: 浦本
B37: =ROW()-ROW($B$4) -> 33 | F37: 繰越額＋当月額 | G37: 同上 | H37: 同上 | K37: OK | L37: 浦本
B38: =ROW()-ROW($B$4) -> 34 | F38: 10%税込み金額 | G38: 同上 | H38: 同上 | K38: OK | L38: 浦本
B39: =ROW()-ROW($B$4) -> 35 | F39: 10%消費税 | G39: 同上 | H39: 同上 | K39: OK | L39: 浦本
B40: =ROW()-ROW($B$4) -> 36 | F40: 8%税込み金額 | G40: 同上 | H40: 同上 | K40: OK | L40: 浦本
B41: =ROW()-ROW($B$4) -> 37 | F41: 8%消費税 | G41: 同上 | H41: 同上 | K41: OK | L41: 浦本
B42: =ROW()-ROW($B$4) -> 38 | F42: 0%対象金額 | G42: 同上 | H42: 同上 | K42: OK | L42: 浦本
...

Sheet 設定
A1: スクリプト プロパテ
A2: SLACK_BOT_TOKEN_CANVAS_ES | B2: xoxb-2164609472-9776604036162-dA8tqZPwZETlBUm2aKYjY2p0
A3: SLACK_BOT_TOKEN_DA | B3: xoxb-2164609472-9858827499537-VzKA8ftMyAqVy4tEynZykaNv
A4: SLACK_BOT_TOKEN_ES | B4: xoxb-2164609472-9769391705459-kWPPk8J8CzVOGe2qo7t0iBZd
A5: SLACK_BOT_TOKEN_TC | B5: xoxb-2164609472-9872333073667-oWEMXzCOp0Ux8AnGbei3fGwZ
A6: SLACK_BOT_TOKEN_TD | B6: xoxb-2164609472-9872865655363-HrlaGMe73lGl2MVs50Uobpnh
A7: SLACK_BOT_TOKEN_TH | B7: xoxb-2164609472-9882831604084-RUvHXPLKha9w0q4qKljqo3sD
A8: SLACK_BOT_TOKEN_TI | B8: xoxb-2164609472-9854370289746-EziVgwlXyIxfdPFSmwy5sjJ1
A9: SLACK_BOT_TOKEN_TK | B9: xoxb-2164609472-9850914590229-kZv7V2PmUHL1eu2BExXDHhrc
A10: SLACK_CHANNEL_ID_DA | B10: C09NALDQB9C
A11: SLACK_CHANNEL_ID_ES | B11: C092ADL9GET
A12: SLACK_CHANNEL_ID_TC | B12: C09RAKVDT1T
A13: SLACK_CHANNEL_ID_TD | B13: C09QTFG2RAS
... A16: SLACK_CHANNEL_ID_TK | B16: C09QZ3DJXBN

Sheet 進捗
B2: テスト進捗
O3: 残項目数 | P3: 総ケース数 | R3: バグ発生数(起票数) | S3: バグ発生率
E4: 未 | F4: NG | G4: 保 | H4: Block | I4: OK | J4: Autify実行 | K4: 外 | L4: - | O4: =SUM(E7:H8) -> 0 | P4: =SUM(E8:K8) -> 123 | R4: 1 | S4: =R4/P4 -> 0.0081300813
B5: テストケース | C5: Win11/ Chrome | D5: - | E5: =countif('テストケース'!$K:$K,E4) -> 0 | F5: =countif('テストケース'!$K:$K,F4) -> 0 | G5: =countif('テストケース'!$K:$K,G4) -> 0 | H5: =countif('テストケース'!$K:$K,H4) -> 0 | I5: =countif('テストケース'!$K:$K,I4) -> 123 | J5: =countif('テストケース'!$K:$K,J4) -> 0 | K5: =countif('テストケース'!$K:$K,K4) -> 0 | L5: =countif('テストケース'!$K:$K,L4) -> 1 | S5: ↑バグ発生数÷テストケース数(再実施含まない)
B6: テスト② | C6: Win11/ Chrome | D6: TK+TI+TD | E6: =COUNTIF('テスト②'!$F:$N,E4) -> #REF! | F6: =COUNTIF('テスト②'!$F:$N,F4) -> #REF! | G6: =COUNTIF('テスト②'!$F:$N,G4) -> #REF! | H6: =COUNTIF('テスト②'!$F:$N,H4) -> #REF! | I6: =COUNTIF('テスト②'!$F:$N,I4) -> #REF! | J6: =COUNTIF('テスト②'!$F:$N,J4) -> #REF! | K6: =COUNTIF('テスト②'!$F:$N,K4) -> #REF! | L6: =COUNTIF('テスト②'!$F:$N,L4) -> #REF!
D8: 合計 | E8: =SUM(E5) -> 0 | F8: =SUM(F5) -> 0 | G8: =SUM(G5) -> 0 | H8: =SUM(H5) -> 0 | I8: =SUM(I5) -> 123 | J8: =SUM(J5) -> 0 | K8: =SUM(K5) -> 0 | L8: =SUM(L5) -> 1

Sheet 質問・レビュー指摘_振り返り
A2: ◾️集計_指摘分類 | B2: 合計 | E2: ◾️集計_指摘原因 | F2: 合計
A3: 指摘分類 | B3: 件数 | C3: 割合 | E3: 指摘原因 | F3: 件数 | G3: 割合
A4: 大きな観点漏れ | E4: ケアレスミス
A5: パターン不足 | E5: 仕様把握もれ(新機能)
A6: パターン過多 | E6: 仕様把握漏れ(既存機能)
A7: リグレッション観点不足 | E7: 仕様共有漏れ
A8: デグレ確認観点不足 | E8: 認識齟齬
A9: 期待値誤り | E9: 影響範囲考慮漏れ(新機能)
A10: 期待値不足 | E10: 影響範囲考慮漏れ(既存機能)
A11: 誤記 | E11: 確認不足
A12: 体裁不備 | E12: その他
A13: わかりにくい | E13: 仕様・要件質問
A14: その他
A15: 仕様・要件質問

Sheet チェック表
B2: ※サブリーダーがチェックする | E2: チェックタイミング
B3: No | C3: 大項目 | D3: チェック内容 | E3: 計画 | F3: 設計 | G3: 実行 | H3: 備考
B4: 1 | C4: リリース時期 | D4: お客様と時期を握ってないか（デッドラインがないか）をチェック。 | E4: 未 | F4: - | G4: -
B5: 2 | D5: 別機能とのバッティングがないかをチェック。 ※リリースノートのTK,TI,TDタグなどを確認 ※推進会で、SL間で確認し合う | E5: 未 | F5: - | G5: -
B6: 3 | C6: 通知 | D6: 通知要否・期間はCSと確認済かをチェック。 | E6: 未 | F6: - | G6: -
B7: 4 | C7: 要件レビュー | D7: 要件の内容にQA視点で不備がないかをチェック。 ※要件レビューチェック表 ※規模の大きい案件に対しては要件確認は対面でPO/開発とすり合わせをする | E7: 未 | F7: - | G7: -
B8: 5 | C8: バグ発生率 | D8: バグ発生率を進捗シートに入力 | E8: - | F8: - | G8: 未
B9: 6 | C9: バグ分析要否確認 | D9: バグ分析が必要かどうかをチェック。 ※QAバグ分析資料 ※以下に当てはまる場合はmustで分析が必要とする ・テストケース数が1000件を超える場合 (リグレッションテストの場合は例外) ・バグ発生率が5.0%を超えていた場合(プロダクト品質の懸念) | E9: - | F9: - | G9: 未
B10: 7 | C10: テスト完了確認 | D10: ・テストケースが全部消化されているかをチェック。 ・「対象外」ステータスは全て妥当かをチェック。 ・バグ発生数が入力済かをチェック。 | E10: - | F10: - | G10: 未
B11: 8 | C11: リリース日最終確認 ＆周知 | D11: リリース日の最終決定をし、開発・CSへ連絡をする ※特に事前通知が必要なものについては強調しておく | E11: - | F11: - | G11: 未

Sheet Markdown Output 20260130_133526
A1: プルリクエスト： https://github.com/TOKIUM/drwallet-worker/pull/5140 | ■観点の目次 | | | | | | | | | | | | | | 実際の画面 | | --- | --- | --- | --- | --- | --- | --- | --- | --- | --- | --- | --- | --- | --- | --- | | 確認すること | | | 画面 | | | 確認対象 | | | 詳細 | | | | | | | 問題の解説編集 | | | 練習問題管理 | | | 編集前 | 表示 | | 「！解説を編集 解説を編集できます。」と表示されていること | | | | | | | | | | | | | | 編集ボタン | | 編集ボタンが表示されていること | | | | | | | | | | | | | | ┗押下 | | 「クリップ項目解説の編集」画面に遷移すること | | | | | | | | | | | | | 解説未設定 | 編集ボタン | | 編集ボタンが表示されていないこと | | | | | | | | | | クリップ項目解説の編集 | | | 表示 | | | 「クリップ項目解説の編集」と表示されていること | | | | | | | | | | | | | | | | ←戻るボタンが表示されていること | | | | | | | | | | | | | | | | 左画面に解説対象の画像が表示されていること | | | | | | | | | | | | | | | | 「解説を保存」ボタンが表示されていること | | | | | | | | | | | | | 編集 | 下記クリップ項目 | | 編集できること | | | | | | | | | | | | | 保存 | 下記クリップ項目 | | 編集した内容で保存できること | | | | | | | 既存機能への影響 | | | 採点結果 | | | 編集前の解説 | 下記クリップ項目 | | 編集前の解説が表示されていること | | | | | | | クリップ項目 | | | | | | | | | | | | | | | | 発行者 | | | ※管理画面の「オペレーターの回答を確認」、成績ページの受験履歴＞「オペレーターの回答を確認する」には解説の記載はないのでテスト対象外 | | | | | | | | | | | | | 電話番号 | | | | | | | | | | | | | | | | 登録番号 | | | | | | | | | | | | | | | | 銀行 | | | | | | | | | | | | | | | | 支払期限 | | | | | | | | | | | | | | | | 振込手数料負担者 | | | | | | | | | | | | | | | | 繰越額＋当月額 | | | | | | | | | | | | | | | | 10%税込み金額 | | | | | | | | | | | | | | | | 10%消費税 | | | | | | | | | | | | | | | | 8%税込み金額 | | | | | | | | | | | | | | | | 8%消費税 | | | | | | | | | | | | | | | | 0%対象金額 | | | | | | | | | | | | | | | | 源泉徴収税額 | | | | | | | | | | | | | | |

Sheet レビュー＆質問
A2: ◾️工数管理 | B2: (人日) | D2: ◾️レビュー状況
A3: 観点作成 | E3: ステータス | F3: 担当者
A4: 観点修正 | D4: QA内相互・TL
A5: ケース作成 | D5: 開発
A6: ケース修正 | D6: PO
A7: 観点修正工数割合
A8: ケース修正工数割合
A11: ◾️テスト観点 | E11: ステータスフロー図(指摘済 → 完了)
B12: 起票者 | C12: 指摘箇所 | D12: 指摘・質問内容 | E12: 回答者 | F12: 修正内容 | G12: 対応ステータス | H12: 指摘分類 | I12: 指摘原因 | J12: 備考
A13: 1
A14: 2
A15: 3
A16: 4
A17: 5
A18: 6
A19: 7
A20: 8
A21: 9
A22: 10
A23: 11
A24: 12
... A38: 26

Sheet バグ一覧
A1: キー | B1: 要約 | C1: ステータス | D1: 作成日 | E1: 解決日 | F1: 課題タイプ | G1: Epic Link | H1: プロジェクト | I1: 報告者 | J1: 担当者 | K1: 優先度 | L1: Story point estimate | M1: 消費時間 | N1: Parent Link
A2: =HYPERLINK("https://beartail.atlassian.net/browse/KH-2812?atlOrigin=eyJpIjoiYzgwYTQ0ZjEyNzQzNGJhN2JmNjEyZTM0NmRhZWZhNjIiLCJwIjoic2hlZXRzLWppcmEifQ","KH-2812") -> KH-2812 | B2: 申請のCSV出力(汎用申請,事前申請,稟議) の仕様確認、調査 | C2: 完了 | D2: 45195.67 | E2: 45202.603 | F2: ストーリー | G2: =HYPERLINK("https://beartail.atlassian.net/browse/KH-2809?atlOrigin=eyJpIjoiYzgwYTQ0ZjEyNzQzNGJhN2JmNjEyZTM0NmRhZWZhNjIiLCJwIjoic2hlZXRzLWppcmEifQ","KH-2809") -> KH-2809 | H2: Keihi | I2: Takeshi Kokubun || ふーが | J2: Takeshi Kokubun || ふーが | K2: Medium
A3: =HYPERLINK("https://beartail.atlassian.net/browse/KH-2813?atlOrigin=eyJpIjoiYzgwYTQ0ZjEyNzQzNGJhN2JmNjEyZTM0NmRhZWZhNjIiLCJwIjoic2hlZXRzLWppcmEifQ","KH-2813") -> KH-2813 | B3: 申請のCSV出力(汎用申請,事前申請,稟議) の仕様確認、調査 | C3: 完了 | D3: 45195.672 | E3: 45202.603 | F3: ストーリー | G3: =HYPERLINK("https://beartail.atlassian.net/browse/KH-2809?atlOrigin=eyJpIjoiYzgwYTQ0ZjEyNzQzNGJhN2JmNjEyZTM0NmRhZWZhNjIiLCJwIjoic2hlZXRzLWppcmEifQ","KH-2809") -> KH-2809 | H3: Keihi | I3: Eiji MATSUMOTO | J3: Eiji MATSUMOTO | K3: Medium
A4: =HYPERLINK("https://beartail.atlassian.net/browse/KH-2859?atlOrigin=eyJpIjoiYzgwYTQ0ZjEyNzQzNGJhN2JmNjEyZTM0NmRhZWZhNjIiLCJwIjoic2hlZXRzLWppcmEifQ","KH-2859") -> KH-2859 | B4: 【CSV出力】出力項目の検討 | C4: 完了 | D4: 45202.66 | E4: 45212.394 | F4: タスク | G4: =HYPERLINK("https://beartail.atlassian.net/browse/KH-2809?atlOrigin=eyJpIjoiYzgwYTQ0ZjEyNzQzNGJhN2JmNjEyZTM0NmRhZWZhNjIiLCJwIjoic2hlZXRzLWppcmEifQ","KH-2809") -> KH-2809 | H4: Keihi | I4: Takeshi Kokubun || ふーが | J4: Eiji MATSUMOTO | K4: High
A5: =HYPERLINK("https://beartail.atlassian.net/browse/KH-2862?atlOrigin=eyJpIjoiYzgwYTQ0ZjEyNzQzNGJhN2JmNjEyZTM0NmRhZWZhNjIiLCJwIjoic2hlZXRzLWppcmEifQ","KH-2862") -> KH-2862 | B5: 【CSV出力】UIの決定 | C5: 完了 | D5: 45202.661 | E5: 45223.633 | F5: タスク | G5: =HYPERLINK("https://beartail.atlassian.net/browse/KH-2809?atlOrigin=eyJpIjoiYzgwYTQ0ZjEyNzQzNGJhN2JmNjEyZTM0NmRhZWZhNjIiLCJwIjoic2hlZXRzLWppcmEifQ","KH-2809") -> KH-2809 | H5: Keihi | I5: Takeshi Kokubun || ふーが | J5: Takeshi Kokubun || ふーが | K5: Medium
A6: =HYPERLINK("https://beartail.atlassian.net/browse/KH-2864?atlOrigin=eyJpIjoiYzgwYTQ0ZjEyNzQzNGJhN2JmNjEyZTM0NmRhZWZhNjIiLCJwIjoic2hlZXRzLWppcmEifQ","KH-2864") -> KH-2864 | B6: 【CSV出力】設計 | C6: 完了 | D6: 45202.662 | E6: 45211.442 | F6: タスク | G6: =HYPERLINK("https://beartail.atlassian.net/browse/KH-2809?atlOrigin=eyJpIjoiYzgwYTQ0ZjEyNzQzNGJhN2JmNjEyZTM0NmRhZWZhNjIiLCJwIjoic2hlZXRzLWppcmEifQ","KH-2809") -> KH-2809 | H6: Keihi | I6: Takeshi Kokubun || ふーが | J6: Takeshi Kokubun || ふーが | K6: Medium
A7: =HYPERLINK("https://beartail.atlassian.net/browse/KH-2902?atlOrigin=eyJpIjoiYzgwYTQ0ZjEyNzQzNGJhN2JmNjEyZTM0NmRhZWZhNjIiLCJwIjoic2hlZXRzLWppcmEifQ","KH-2902") -> KH-2902 | B7: 経費精算のCSVファイル生成【バックエンド】 | C7: 完了 | D7: 45210.732 | E7: 45216.6 | F7: タスク | G7: =HYPERLINK("https://beartail.atlassian.net/browse/KH-2809?atlOrigin=eyJpIjoiYzgwYTQ0ZjEyNzQzNGJhN2JmNjEyZTM0NmRhZWZhNjIiLCJwIjoic2hlZXRzLWppcmEifQ","KH-2809") -> KH-2809 | H7: Keihi | I7: Takeshi Kokubun || ふーが | J7: Takeshi Kokubun || ふーが | K7: Medium
A8: =HYPERLINK("https://beartail.atlassian.net/browse/KH-2903?atlOrigin=eyJpIjoiYzgwYTQ0ZjEyNzQzNGJhN2JmNjEyZTM0NmRhZWZhNjIiLCJwIjoic2hlZXRzLWppcmEifQ","KH-2903") -> KH-2903 | B8: CSVファイルのS3へのアップロード【バックエンド】 | C8: 完了 | D8: 45210.732 | E8: 45229.821 | F8: タスク | G8: =HYPERLINK("https://beartail.atlassian.net/browse/KH-2809?atlOrigin=eyJpIjoiYzgwYTQ0ZjEyNzQzNGJhN2JmNjEyZTM0NmRhZWZhNjIiLCJwIjoic2hlZXRzLWppcmEifQ","KH-2809") -> KH-2809 | H8: Keihi | I8: Takeshi Kokubun || ふーが | J8: Eiji MATSUMOTO | K8: Medium
A9: =HYPERLINK("https://beartail.atlassian.net/browse/KH-2905?atlOrigin=eyJpIjoiYzgwYTQ0ZjEyNzQzNGJhN2JmNjEyZTM0NmRhZWZhNjIiLCJwIjoic2hlZXRzLWppcmEifQ","KH-2905") -> KH-2905 | B9: コントローラーでCSV生成Jobを起動する【バックエンド】 | C9: 完了 | D9: 45210.734 | E9: 45229.822 | F9: タスク | G9: =HYPERLINK("https://beartail.atlassian.net/browse/KH-2809?atlOrigin=eyJpIjoiYzgwYTQ0ZjEyNzQzNGJhN2JmNjEyZTM0NmRhZWZhNjIiLCJwIjoic2hlZXRzLWppcmEifQ","KH-2809") -> KH-2809 | H9: Keihi | I9: Takeshi Kokubun || ふーが | J9: Eiji MATSUMOTO | K9: Medium
A10: =HYPERLINK("https://beartail.atlassian.net/browse/KH-2897?atlOrigin=eyJpIjoiYzgwYTQ0ZjEyNzQzNGJhN2JmNjEyZTM0NmRhZWZhNjIiLCJwIjoic2hlZXRzLWppcmEifQ","KH-2897") -> KH-2897 | B10: ダウンロードモーダルを表示する【フロントエンド】 | C10: 完了 | D10: 45210.728 | E10: 45245.373 | F10: タスク | G10: =HYPERLINK("https://beartail.atlassian.net/browse/KH-2809?atlOrigin=eyJpIjoiYzgwYTQ0ZjEyNzQzNGJhN2JmNjEyZTM0NmRhZWZhNjIiLCJwIjoic2hlZXRzLWppcmEifQ","KH-2809") -> KH-2809 | H10: Keihi | I10: Takeshi Kokubun || ふーが | J10: Takeshi Kokubun || ふーが | K10: Medium
A11: =HYPERLINK("https://beartail.atlassian.net/browse/KH-2906?atlOrigin=eyJpIjoiYzgwYTQ0ZjEyNzQzNGJhN2JmNjEyZTM0NmRhZWZhNjIiLCJwIjoic2hlZXRzLWppcmEifQ","KH-2906") -> KH-2906 | B11: コントローラーでJobTrackerの一覧を取得する【バックエンド】 | C11: 完了 | D11: 45210.734 | E11: 45243.634 | F11: タスク | G11: =HYPERLINK("https://beartail.atlassian.net/browse/KH-2809?atlOrigin=eyJpIjoiYzgwYTQ0ZjEyNzQzNGJhN2JmNjEyZTM0NmRhZWZhNjIiLCJwIjoic2hlZXRzLWppcmEifQ","KH-2809") -> KH-2809 | H11: Keihi | I11: Takeshi Kokubun || ふーが | J11: Eiji MATSUMOTO | K11: Medium
A12: =HYPERLINK("https://beartail.atlassian.net/browse/KH-2898?atlOrigin=eyJpIjoiYzgwYTQ0ZjEyNzQzNGJhN2JmNjEyZTM0NmRhZWZhNjIiLCJwIjoic2hlZXRzLWppcmEifQ","KH-2898") -> KH-2898 | B12: 「データ作成を開始する」ボタンをモーダルに表示する【フロントエンド】 | C12: 完了 | D12: 45210.729 | E12: 45244.727 | F12: タスク | G12: =HYPERLINK("https://beartail.atlassian.net/browse/KH-2809?atlOrigin=eyJpIjoiYzgwYTQ0ZjEyNzQzNGJhN2JmNjEyZTM0NmRhZWZhNjIiLCJwIjoic2hlZXRzLWppcmEifQ","KH-2809") -> KH-2809 | H12: Keihi | I12: Takeshi Kokubun || ふーが | J12: Takeshi Kokubun || ふーが | K12: Medium
A13: =HYPERLINK("https://beartail.atlassian.net/browse/KH-2900?atlOrigin=eyJpIjoiYzgwYTQ0ZjEyNzQzNGJhN2JmNjEyZTM0NmRhZWZhNjIiLCJwIjoic2hlZXRzLWppcmEifQ","KH-2900") -> KH-2900 | B13: 取得した経費レポートの一覧をテーブル形式で表示する【フロントエンド】 | C13: 完了 | D13: 45210.729 | E13: 45245.372 | F13: タスク | G13: =HYPERLINK("https://beartail.atlassian.net/browse/KH-2809?atlOrigin=eyJpIjoiYzgwYTQ0ZjEyNzQzNGJhN2JmNjEyZTM0NmRhZWZhNjIiLCJwIjoic2hlZXRzLWppcmEifQ","KH-2809") -> KH-2809 | H13: Keihi | I13: Takeshi Kokubun || ふーが | J13: Eiji MATSUMOTO | K13: Medium
A14: =HYPERLINK("https://beartail.atlassian.net/browse/KH-2899?atlOrigin=eyJpIjoiYzgwYTQ0ZjEyNzQzNGJhN2JmNjEyZTM0NmRhZWZhNjIiLCJwIjoic2hlZXRzLWppcmEifQ","KH-2899") -> KH-2899 | B14: 3秒に1回、繰り返し経費レポートの一覧を取得する【フロントエンド】 | C14: 完了 | D14: 45210.729 | E14: 45245.372 | F14: タスク | G14: =HYPERLINK("https://beartail.atlassian.net/browse/KH-2809?atlOrigin=eyJpIjoiYzgwYTQ0ZjEyNzQzNGJhN2JmNjEyZTM0NmRhZWZhNjIiLCJwIjoic2hlZXRzLWppcmEifQ","KH-2809") -> KH-2809 | H14: Keihi | I14: Takeshi Kokubun || ふーが | J14: Eiji MATSUMOTO | K14: Medium
A15: =HYPERLINK("https://beartail.atlassian.net/browse/KH-2901?atlOrigin=eyJpIjoiYzgwYTQ0ZjEyNzQzNGJhN2JmNjEyZTM0NmRhZWZhNjIiLCJwIjoic2hlZXRzLWppcmEifQ","KH-2901") -> KH-2901 | B15: 「ダウンロード」ボタンクリック時、経費レポートをダウンロードする【フロントエンド】 | C15: 完了 | D15: 45210.73 | E15: 45245.373 | F15: タスク | G15: =HYPERLINK("https://beartail.atlassian.net/browse/KH-2809?atlOrigin=eyJpIjoiYzgwYTQ0ZjEyNzQzNGJhN2JmNjEyZTM0NmRhZWZhNjIiLCJwIjoic2hlZXRzLWppcmEifQ","KH-2809") -> KH-2809 | H15: Keihi | I15: Takeshi Kokubun || ふーが | J15: Eiji MATSUMOTO | K15: Medium
A16: =HYPERLINK("https://beartail.atlassian.net/browse/KH-3039?atlOrigin=eyJpIjoiYzgwYTQ0ZjEyNzQzNGJhN2JmNjEyZTM0NmRhZWZhNjIiLCJwIjoic2hlZXRzLWppcmEifQ","KH-3039") -> KH-3039 | B16: 仕訳フォーマット選択時にもCSV出力ができるようにする | C16: 完了 | D16: 45237.672 | E16: 45245.395 | F16: タスク | G16: =HYPERLINK("https://beartail.atlassian.net/browse/KH-2809?atlOrigin=eyJpIjoiYzgwYTQ0ZjEyNzQzNGJhN2JmNjEyZTM0NmRhZWZhNjIiLCJwIjoic2hlZXRzLWppcmEifQ","KH-2809") -> KH-2809 | H16: Keihi | I16: Takeshi Kokubun || ふーが | J16: Eiji MATSUMOTO | K16: Medium
A17: =HYPERLINK("https://beartail.atlassian.net/browse/KH-3041?atlOrigin=eyJpIjoiYzgwYTQ0ZjEyNzQzNGJhN2JmNjEyZTM0NmRhZWZhNjIiLCJwIjoic2hlZXRzLWppcmEifQ","KH-3041") -> KH-3041 | B17: カスタムフォーマット選択時にもCSV出力ができるようにする | C17: 完了 | D17: 45237.672 | E17: 45252.571 | F17: タスク | G17: =HYPERLINK("https://beartail.atlassian.net/browse/KH-2809?atlOrigin=eyJpIjoiYzgwYTQ0ZjEyNzQzNGJhN2JmNjEyZTM0NmRhZWZhNjIiLCJwIjoic2hlZXRzLWppcmEifQ","KH-2809") -> KH-2809 | H17: Keihi | I17: Takeshi Kokubun || ふーが | J17: Takeshi Kokubun || ふーが | K17: Medium
A18: =HYPERLINK("https://beartail.atlassian.net/browse/KH-3089?atlOrigin=eyJpIjoiYzgwYTQ0ZjEyNzQzNGJhN2JmNjEyZTM0NmRhZWZhNjIiLCJwIjoic2hlZXRzLWppcmEifQ","KH-3089") -> KH-3089 | B18: 上限の1万件に対する動作とパフォーマンスを評価する | C18: 完了 | D18: 45244.663 | E18: 45252.845 | F18: タスク | G18: =HYPERLINK("https://beartail.atlassian.net/browse/KH-2809?atlOrigin=eyJpIjoiYzgwYTQ0ZjEyNzQzNGJhN2JmNjEyZTM0NmRhZWZhNjIiLCJwIjoic2hlZXRzLWppcmEifQ","KH-2809") -> KH-2809 | H18: Keihi | I18: Eiji MATSUMOTO | J18: Takeshi Kokubun || ふーが | K18: Medium
A19: =HYPERLINK("https://beartail.atlassian.net/browse/KH-3120?atlOrigin=eyJpIjoiYzgwYTQ0ZjEyNzQzNGJhN2JmNjEyZTM0NmRhZWZhNjIiLCJwIjoic2hlZXRzLWppcmEifQ","KH-3120") -> KH-3120 | B19: 件数制限に関するエラーメッセージ表示の仕様検討 | C19: 完了 | D19: 45251.648 | E19: 45257.418 | F19: タスク | G19: =HYPERLINK("https://beartail.atlassian.net/browse/KH-2809?atlOrigin=eyJpIjoiYzgwYTQ0ZjEyNzQzNGJhN2JmNjEyZTM0NmRhZWZhNjIiLCJwIjoic2hlZXRzLWppcmEifQ","KH-2809") -> KH-2809 | H19: Keihi | I19: Takeshi Kokubun || ふーが | J19: Takeshi Kokubun || ふーが | K19: Medium
A20: =HYPERLINK("https://beartail.atlassian.net/browse/KH-3126?atlOrigin=eyJpIjoiYzgwYTQ0ZjEyNzQzNGJhN2JmNjEyZTM0NmRhZWZhNjIiLCJwIjoic2hlZXRzLWppcmEifQ","KH-3126") -> KH-3126 | B20: CSVダウンロードモーダルに上限件数に関するガイドを設置する | C20: 完了 | D20: 45251.701 | E20: 45261.52 | F20: タスク | G20: =HYPERLINK("https://beartail.atlassian.net/browse/KH-2809?atlOrigin=eyJpIjoiYzgwYTQ0ZjEyNzQzNGJhN2JmNjEyZTM0NmRhZWZhNjIiLCJwIjoic2hlZXRzLWppcmEifQ","KH-2809") -> KH-2809 | H20: Keihi | I20: Takeshi Kokubun || ふーが | J20: Takeshi Kokubun || ふーが | K20: Medium
A21: =HYPERLINK("https://beartail.atlassian.net/browse/KH-3125?atlOrigin=eyJpIjoiYzgwYTQ0ZjEyNzQzNGJhN2JmNjEyZTM0NmRhZWZhNjIiLCJwIjoic2hlZXRzLWppcmEifQ","KH-3125") -> KH-3125 | B21: (不要になったのでクローズ)(QA)ファイル出力モーダルにて？の部分にホバーすると出力出来る件数が更新されていない | C21: 完了 | D21: 45251.698 | E21: 45261.484 | F21: QA修正依頼 | G21: =HYPERLINK("https://beartail.atlassian.net/browse/KH-2809?atlOrigin=eyJpIjoiYzgwYTQ0ZjEyNzQzNGJhN2JmNjEyZTM0NmRhZWZhNjIiLCJwIjoic2hlZXRzLWppcmEifQ","KH-2809") -> KH-2809 | H21: Keihi | I21: kanada_r | J21: Takeshi Kokubun || ふーが | K21: Medium
A22: =HYPERLINK("https://beartail.atlassian.net/browse/KH-3127?atlOrigin=eyJpIjoiYzgwYTQ0ZjEyNzQzNGJhN2JmNjEyZTM0NmRhZWZhNjIiLCJwIjoic2hlZXRzLWppcmEifQ","KH-3127") -> KH-3127 | B22: (インシデントで対応)(QA)ファイル出力モーダルにてダウンロードしようとした際に500エラーでダウンロード出来ない | C22: 完了 | D22: 45251.704 | E22: 45261.445 | F22: QA修正依頼 | G22: =HYPERLINK("https://beartail.atlassian.net/browse/KH-2809?atlOrigin=eyJpIjoiYzgwYTQ0ZjEyNzQzNGJhN2JmNjEyZTM0NmRhZWZhNjIiLCJwIjoic2hlZXRzLWppcmEifQ","KH-2809") -> KH-2809 | H22: Keihi | I22: kanada_r | J22: Takeshi Kokubun || ふーが | K22: Medium
A23: =HYPERLINK("https://beartail.atlassian.net/browse/KH-3129?atlOrigin=eyJpIjoiYzgwYTQ0ZjEyNzQzNGJhN2JmNjEyZTM0NmRhZWZhNjIiLCJwIjoic2hlZXRzLWppcmEifQ","KH-3129") -> KH-3129 | B23: 出力対象が経費10,000件を超える場合でもエラーにはせず上限件数までのCSVを生成する | C23: 完了 | D23: 45252.577 | E23: 45272.706 | F23: タスク | G23: =HYPERLINK("https://beartail.atlassian.net/browse/KH-2809?atlOrigin=eyJpIjoiYzgwYTQ0ZjEyNzQzNGJhN2JmNjEyZTM0NmRhZWZhNjIiLCJwIjoic2hlZXRzLWppcmEifQ","KH-2809") -> KH-2809 | H23: Keihi | I23: Takeshi Kokubun || ふーが | J23: Takeshi Kokubun || ふーが | K23: Medium
A24: =HYPERLINK("https://beartail.atlassian.net/browse/KH-3149?atlOrigin=eyJpIjoiYzgwYTQ0ZjEyNzQzNGJhN2JmNjEyZTM0NmRhZWZhNjIiLCJwIjoic2hlZXRzLWppcmEifQ","KH-3149") -> KH-3149 | B24: (QA)経費精算側をダウンロードした際にファイル名が出力形式の名前ではないので分かりにくい | C24: 完了 | D24: 45257.651 | E24: 45271.601 | F24: QA修正依頼 | G24: =HYPERLINK("https://beartail.atlassian.net/browse/KH-2809?atlOrigin=eyJpIjoiYzgwYTQ0ZjEyNzQzNGJhN2JmNjEyZTM0NmRhZWZhNjIiLCJwIjoic2hlZXRzLWppcmEifQ","KH-2809") -> KH-2809 | H24: Keihi | I24: kanada_r | J24: Takeshi Kokubun || ふーが | K24: Medium
A25: =HYPERLINK("https://beartail.atlassian.net/browse/KH-3150?atlOrigin=eyJpIjoiYzgwYTQ0ZjEyNzQzNGJhN2JmNjEyZTM0NmRhZWZhNjIiLCJwIjoic2hlZXRzLWppcmEifQ","KH-3150") -> KH-3150 | B25: (再QA完)(QA)英語化した際に経費精算側の「最新出力ファイル作成を開始」ボタンが英語化されていない | C25: 完了 | D25: 45257.721 | E25: 45268.736 | F25: QA修正依頼 | G25: =HYPERLINK("https://beartail.atlassian.net/browse/KH-2809?atlOrigin=eyJpIjoiYzgwYTQ0ZjEyNzQzNGJhN2JmNjEyZTM0NmRhZWZhNjIiLCJwIjoic2hlZXRzLWppcmEifQ","KH-2809") -> KH-2809 | H25: Keihi | I25: kanada_r | J25: Takeshi Kokubun || ふーが | K25: Medium
A26: =HYPERLINK("https://beartail.atlassian.net/browse/KH-3228?atlOrigin=eyJpIjoiYzgwYTQ0ZjEyNzQzNGJhN2JmNjEyZTM0NmRhZWZhNjIiLCJwIjoic2hlZXRzLWppcmEifQ","KH-3228") -> KH-3228 | B26: (QA)代理人ログインの場合に「この条件で会計データ作成を開始」が表示されている箇所がある | C26: 完了 | D26: 45271.646 | E26: 45279.74 | F26: QA修正依頼 | G26: =HYPERLINK("https://beartail.atlassian.net/browse/KH-2809?atlOrigin=eyJpIjoiYzgwYTQ0ZjEyNzQzNGJhN2JmNjEyZTM0NmRhZWZhNjIiLCJwIjoic2hlZXRzLWppcmEifQ","KH-2809") -> KH-2809 | H26: Keihi | I26: kanada_r | J26: Takeshi Kokubun || ふーが | K26: Medium
A27: =HYPERLINK("https://beartail.atlassian.net/browse/KH-3234?atlOrigin=eyJpIjoiYzgwYTQ0ZjEyNzQzNGJhN2JmNjEyZTM0NmRhZWZhNjIiLCJwIjoic2hlZXRzLWppcmEifQ","KH-3234") -> KH-3234 | B27: api/v1/reports_controller の Arch チェック対応 | C27: 完了 | D27: 45272.615 | E27: 45287.061 | F27: タスク | G27: =HYPERLINK("https://beartail.atlassian.net/browse/KH-2809?atlOrigin=eyJpIjoiYzgwYTQ0ZjEyNzQzNGJhN2JmNjEyZTM0NmRhZWZhNjIiLCJwIjoic2hlZXRzLWppcmEifQ","KH-2809") -> KH-2809 | H27: Keihi | I27: Takeshi Kokubun || ふーが | J27: Takeshi Kokubun || ふーが | K27: Medium
A28: =HYPERLINK("https://beartail.atlassian.net/browse/KH-3226?atlOrigin=eyJpIjoiYzgwYTQ0ZjEyNzQzNGJhN2JmNjEyZTM0NmRhZWZhNjIiLCJwIjoic2hlZXRzLWppcmEifQ","KH-3226") -> KH-3226 | B28: (再QA完)(QA)ファイル出力モーダルにて内容が重複している箇所がある | C28: 完了 | D28: 45271.612 | E28: 45272.65 | F28: QA修正依頼 | G28: =HYPERLINK("https://beartail.atlassian.net/browse/KH-2809?atlOrigin=eyJpIjoiYzgwYTQ0ZjEyNzQzNGJhN2JmNjEyZTM0NmRhZWZhNjIiLCJwIjoic2hlZXRzLWppcmEifQ","KH-2809") -> KH-2809 | H28: Keihi | I28: kanada_r | J28: Takeshi Kokubun || ふーが | K28: Medium
A29: =HYPERLINK("https://beartail.atlassian.net/browse/KH-3284?atlOrigin=eyJpIjoiYzgwYTQ0ZjEyNzQzNGJhN2JmNjEyZTM0NmRhZWZhNjIiLCJwIjoic2hlZXRzLWppcmEifQ","KH-3284") -> KH-3284 | B29: 「事前申請のCSV出力」見積もりのための調査 | C29: 完了 | D29: 45279.645 | E29: 45286.618 | F29: タスク | G29: =HYPERLINK("https://beartail.atlassian.net/browse/KH-2809?atlOrigin=eyJpIjoiYzgwYTQ0ZjEyNzQzNGJhN2JmNjEyZTM0NmRhZWZhNjIiLCJwIjoic2hlZXRzLWppcmEifQ","KH-2809") -> KH-2809 | H29: Keihi | I29: Takeshi Kokubun || ふーが | J29: Takeshi Kokubun || ふーが | K29: Medium
A30: =HYPERLINK("https://beartail.atlassian.net/browse/KH-3227?atlOrigin=eyJpIjoiYzgwYTQ0ZjEyNzQzNGJhN2JmNjEyZTM0NmRhZWZhNjIiLCJwIjoic2hlZXRzLWppcmEifQ","KH-3227") -> KH-3227 | B30: (対応なし)(QA)（懸念点）出力件数が10000件に増えたことでメール送信がエラーになる可能性がある | C30: 完了 | D30: 45271.626 | E30: 45272.53 | F30: QA修正依頼 | G30: =HYPERLINK("https://beartail.atlassian.net/browse/KH-2809?atlOrigin=eyJpIjoiYzgwYTQ0ZjEyNzQzNGJhN2JmNjEyZTM0NmRhZWZhNjIiLCJwIjoic2hlZXRzLWppcmEifQ","KH-2809") -> KH-2809 | H30: Keihi | I30: kanada_r | K30: Medium
A31: =HYPERLINK("https://beartail.atlassian.net/browse/KH-3313?atlOrigin=eyJpIjoiYzgwYTQ0ZjEyNzQzNGJhN2JmNjEyZTM0NmRhZWZhNjIiLCJwIjoic2hlZXRzLWppcmEifQ","KH-3313") -> KH-3313 | B31: 事前申請CSV出力の仕様を固める | C31: 完了 | D31: 45286.624 | E31: 45301.74 | F31: タスク | G31: =HYPERLINK("https://beartail.atlassian.net/browse/KH-2809?atlOrigin=eyJpIjoiYzgwYTQ0ZjEyNzQzNGJhN2JmNjEyZTM0NmRhZWZhNjIiLCJwIjoic2hlZXRzLWppcmEifQ","KH-2809") -> KH-2809 | H31: Keihi | I31: Takeshi Kokubun || ふーが | J31: Takeshi Kokubun || ふーが | K31: Medium
A32: =HYPERLINK("https://beartail.atlassian.net/browse/KH-3317?atlOrigin=eyJpIjoiYzgwYTQ0ZjEyNzQzNGJhN2JmNjEyZTM0NmRhZWZhNjIiLCJwIjoic2hlZXRzLWppcmEifQ","KH-3317") -> KH-3317 | B32: 汎用申請CSV出力の調査 | C32: 完了 | D32: 45286.641 | E32: 45301.741 | F32: タスク | G32: =HYPERLINK("https://beartail.atlassian.net/browse/KH-2809?atlOrigin=eyJpIjoiYzgwYTQ0ZjEyNzQzNGJhN2JmNjEyZTM0NmRhZWZhNjIiLCJwIjoic2hlZXRzLWppcmEifQ","KH-2809") -> KH-2809 | H32: Keihi | I32: Takeshi Kokubun || ふーが | J32: Takeshi Kokubun || ふーが | K32: Medium
A33: =HYPERLINK("https://beartail.atlassian.net/browse/KH-3338?atlOrigin=eyJpIjoiYzgwYTQ0ZjEyNzQzNGJhN2JmNjEyZTM0NmRhZWZhNjIiLCJwIjoic2hlZXRzLWppcmEifQ","KH-3338") -> KH-3338 | B33: 【事前申請】タブに出力ボタンを設置、クリックでモーダルを表示する | C33: 完了 | D33: 45300.651 | E33: 45307.64 | F33: タスク | G33: =HYPERLINK("https://beartail.atlassian.net/browse/KH-2809?atlOrigin=eyJpIjoiYzgwYTQ0ZjEyNzQzNGJhN2JmNjEyZTM0NmRhZWZhNjIiLCJwIjoic2hlZXRzLWppcmEifQ","KH-2809") -> KH-2809 | H33: Keihi | I33: Takeshi Kokubun || ふーが | J33: Takeshi Kokubun || ふーが | K33: Medium
A34: =HYPERLINK("https://beartail.atlassian.net/browse/KH-3348?atlOrigin=eyJpIjoiYzgwYTQ0ZjEyNzQzNGJhN2JmNjEyZTM0NmRhZWZhNjIiLCJwIjoic2hlZXRzLWppcmEifQ","KH-3348") -> KH-3348 | B34: 【事前申請】「ファイル作成を開始」ボタンを押すとCSVデータが生成されS3にアップロードされる | C34: 完了 | D34: 45303.45 | E34: 45321.658 | F34: タスク | G34: =HYPERLINK("https://beartail.atlassian.net/browse/KH-2809?atlOrigin=eyJpIjoiYzgwYTQ0ZjEyNzQzNGJhN2JmNjEyZTM0NmRhZWZhNjIiLCJwIjoic2hlZXRzLWppcmEifQ","KH-2809") -> KH-2809 | H34: Keihi | I34: Takeshi Kokubun || ふーが | J34: Takeshi Kokubun || ふーが | K34: Medium
A35: =HYPERLINK("https://beartail.atlassian.net/browse/KH-3252?atlOrigin=eyJpIjoiYzgwYTQ0ZjEyNzQzNGJhN2JmNjEyZTM0NmRhZWZhNjIiLCJwIjoic2hlZXRzLWppcmEifQ","KH-3252") -> KH-3252 | B35: (再QA完)(仕様確認)ファイル出力モーダル_取引日付の一括指定を入力しているが、仕訳フォーマットに出力されない | C35: 完了 | D35: 45273.762 | E35: 45278.481 | F35: QA修正依頼 | G35: =HYPERLINK("https://beartail.atlassian.net/browse/KH-2809?atlOrigin=eyJpIjoiYzgwYTQ0ZjEyNzQzNGJhN2JmNjEyZTM0NmRhZWZhNjIiLCJwIjoic2hlZXRzLWppcmEifQ","KH-2809") -> KH-2809 | H35: Keihi | I35: 本橋 遼 | J35: Eiji MATSUMOTO | K35: Lowest
A36: =HYPERLINK("https://beartail.atlassian.net/browse/KH-3253?atlOrigin=eyJpIjoiYzgwYTQ0ZjEyNzQzNGJhN2JmNjEyZTM0NmRhZWZhNjIiLCJwIjoic2hlZXRzLWppcmEifQ","KH-3253") -> KH-3253 | B36: （QA確認完了）承認一覧の出力ボタンを押してもダウンロードが実行されずモーダルが表示される | C36: 完了 | D36: 45273.772 | E36: 45278.489 | F36: バグ | G36: =HYPERLINK("https://beartail.atlassian.net/browse/KH-2809?atlOrigin=eyJpIjoiYzgwYTQ0ZjEyNzQzNGJhN2JmNjEyZTM0NmRhZWZhNjIiLCJwIjoic2hlZXRzLWppcmEifQ","KH-2809") -> KH-2809 | H36: Keihi | I36: Takeshi Kokubun || ふーが | J36: Eiji MATSUMOTO | K36: Medium
A37: =HYPERLINK("https://beartail.atlassian.net/browse/KH-3258?atlOrigin=eyJpIjoiYzgwYTQ0ZjEyNzQzNGJhN2JmNjEyZTM0NmRhZWZhNjIiLCJwIjoic2hlZXRzLWppcmEifQ","KH-3258") -> KH-3258 | B37: 承認一覧の出力ボタンを押してもダウンロードが実行されずモーダルが表示される | C37: クローズ | D37: 45275.586 | F37: QA | G37: =HYPERLINK("https://beartail.atlassian.net/browse/KH-2809?atlOrigin=eyJpIjoiYzgwYTQ0ZjEyNzQzNGJhN2JmNjEyZTM0NmRhZWZhNjIiLCJwIjoic2hlZXRzLWppcmEifQ","KH-2809") -> KH-2809 | H37: Keihi | I37: Takeshi Kokubun || ふーが | K37: Medium
A38: =HYPERLINK("https://beartail.atlassian.net/browse/KH-3349?atlOrigin=eyJpIjoiYzgwYTQ0ZjEyNzQzNGJhN2JmNjEyZTM0NmRhZWZhNjIiLCJwIjoic2hlZXRzLWppcmEifQ","KH-3349") -> KH-3349 | B38: 【事前申請】モーダルに生成履歴の最新5件を表示し、ダウンロードできるようにする | C38: 完了 | D38: 45303.517 | E38: 45335.608 | F38: タスク | G38: =HYPERLINK("https://beartail.atlassian.net/browse/KH-2809?atlOrigin=eyJpIjoiYzgwYTQ0ZjEyNzQzNGJhN2JmNjEyZTM0NmRhZWZhNjIiLCJwIjoic2hlZXRzLWppcmEifQ","KH-2809") -> KH-2809 | H38: Keihi | I38: Takeshi Kokubun || ふーが | J38: Takeshi Kokubun || ふーが | K38: Medium
A39: =HYPERLINK("https://beartail.atlassian.net/browse/KH-3350?atlOrigin=eyJpIjoiYzgwYTQ0ZjEyNzQzNGJhN2JmNjEyZTM0NmRhZWZhNjIiLCJwIjoic2hlZXRzLWppcmEifQ","KH-3350") -> KH-3350 | B39: 【事前申請】モーダルは3秒に1回、最新のファイル生成履歴を取得する | C39: 完了 | D39: 45303.519 | E39: 45338.679 | F39: タスク | G39: =HYPERLINK("https://beartail.atlassian.net/browse/KH-2809?atlOrigin=eyJpIjoiYzgwYTQ0ZjEyNzQzNGJhN2JmNjEyZTM0NmRhZWZhNjIiLCJwIjoic2hlZXRzLWppcmEifQ","KH-2809") -> KH-2809 | H39: Keihi | I39: Takeshi Kokubun || ふーが | J39: Takeshi Kokubun || ふーが | K39: Medium
A40: =HYPERLINK("https://beartail.atlassian.net/browse/KH-3523?atlOrigin=eyJpIjoiYzgwYTQ0ZjEyNzQzNGJhN2JmNjEyZTM0NmRhZWZhNjIiLCJwIjoic2hlZXRzLWppcmEifQ","KH-3523") -> KH-3523 | B40: 【事前申請】出力上限を事前申請 1 万件までに制限する | C40: 完了 | D40: 45323.61 | E40: 45335.608 | F40: タスク | G40: =HYPERLINK("https://beartail.atlassian.net/browse/KH-2809?atlOrigin=eyJpIjoiYzgwYTQ0ZjEyNzQzNGJhN2JmNjEyZTM0NmRhZWZhNjIiLCJwIjoic2hlZXRzLWppcmEifQ","KH-2809") -> KH-2809 | H40: Keihi | I40: Takeshi Kokubun || ふーが | J40: Takeshi Kokubun || ふーが | K40: Medium
...

Sheet old_チェック表
B2: ※サブリーダーがチェックする | E2: チェックタイミング
B3: No | C3: 大項目 | D3: チェック内容 | E3: 計画 | F3: 設計 | G3: 実行 | H3: 結果 | I3: 備考
B4: 1 | C4: リリース時期 | D4: お客様と時期を握ってないか（デッドラインがないか） | H4: 未
B5: 2 | D5: 別機能とのバッティングがないか | H5: 未
B6: 3 | C6: 通知 | D6: 通知要否・期間はCSと確認済か | H6: 未
B7: 4 | C7: 要件レビュー | D7: 要件の内容にQA視点で不備がないか ※要件レビューチェック観点を要作成 | H7: 未
B8: 5 | C8: テスト密度 | D8: 数値が目標値内か。 目標値と大きく乖離している場合、テストケースの見直しも検討。 ※機能数の指標は要整理 | H8: 未
B9: 6 | C9: バグ発生率 | D9: 数値が目標値内か。 目標値と大きく乖離している場合、追加テストも検討。 | H9: 未
B10: 7 | C10: テスト完了確認 | D10: ・テストケースが全部消化されているか ・「対象外」ステータスは全て妥当か | H10: 未
H14: テスト観点レビュー | J14: テスト完了後レビュー | L14: 対象アウトプット
B15: No | C15: タイミング | D15: 内容 | E15: 締め切りタイミング | F15: チェック者 | G15: レビュー結果 | H15: テスト設計者 | I15: TLレビュー | J15: テスト実行者 | K15: TLレビュー
B16: 1 | C16: 開発計画全体 | D16: リリースまでの残作業は全て洗出し、スケジュール化されているか ※JIRAチケットをテンプレートから作成し、実施が必要なタスクを確認する | F16: サブリーダー | L16: JIRAの起票が完了している
B17: =B16+1 -> 2 | D17: 変更含む、要件が開発から接続されているか | E17: テスト設計完了までに | L17: ①tspecがapproveされている ②必要な要件ドキュメントリスト
B18: =B17+1 -> 3 | D18: 作業体制、有識者、経験者不足、外注手配など対応、確保対策は取られているか | J18: － | K18: － | L18: 体制表
B19: =B18+1 -> 4 | C19: テスト計画 | D19: テスト環境の準備、実行計画に問題無いか | K19: － | L19: テスト項目書_チェック表
B20: =B19+1 -> 5 | D20: 品質チェック密度(テスト密度・バグ摘出率・カバレッジ・再テスト実施率)は目標値を設定しているか、その根拠、理由は明確か ※ | J20: － | K20: － | L20: テスト項目書_チェック表
B21: =B20+1 -> 6 | D21: 「概要」シートにおける「今回プロジェクトの要否」(F列)は全て記載されているか | J21: － | K21: － | L21: テスト項目書_概要シート
B22: =B21+1 -> 7 | D22: 「概要」シートにおける「開発チーム実施対象テスト要否」(H列)は全て記載されており、開発と認識が揃っているか | J22: － | K22: － | L22: テスト項目書_概要シート
B23: =B22+1 -> 8 | D23: 同時並行の案件の機能バッティング、マージスケジュールの確認 | L23: テスト項目書_概要シート
B24: =B23+1 -> 9 | D24: (任意)過去市場バグの教訓は意識されているか | H24: － | I24: － | J24: － | K24: － | L24: －
B25: =B24+1 -> 10 | C25: テスト設計 | D25: レビュー指摘、是正は完了しているか | E25: テスト開始前 | F25: テスト設計者 | L25: テスト項目書_レビュー指摘表
B26: =B25+1 -> 11 | D26: テスト設計時点で評価可能なテスト有効性項目(テスト密度・カバレッジ)は、目標値を達成しているか ※ | E26: テスト開始前 | L26: テスト項目書_チェック表
B27: =B26+1 -> 12 | D27: 各種レビュー、検査は規定通り実施されたか、指摘、是正は完了しているか | E27: テスト開始前 | L27: テスト項目書_チェック表
B28: =B27+1 -> 13 | D28: 同時並行の案件の機能バッティング、マージスケジュールの確認 | E28: テスト開始前
B29: =B28+1 -> 14 | C29: テスト実施 | D29: デプロイなどSI対象リソース、環境構築、セットアップデータに漏れはないか | E29: テスト開始前 | H29: － | I29: － | L29: 開発に確認いただく
B30: =B29+1 -> 15 | D30: 課題管理（仕様、業務、技術、外部要因など）は全て解決しているか | H30: － | I30: － | L30: JIRA_課題チケット
B31: =B30+1 -> 16 | D31: 全テスト計画、項目を消化しているか | H31: － | I31: － | L31: テスト項目書_進捗
B32: =B31+1 -> 17 | D32: 発生した不良は全て解決しているか（対策含む） | H32: － | I32: － | L32: テスト項目書_チェック表
B33: =B32+1 -> 18 | D33: バグ発生傾向から想定される対策（暫定、恒久）は済んでいるか | H33: － | I33: － | L33: テスト項目書_バグ傾向
B34: =B33+1 -> 19 | D34: 作業スケジュール上の実施状況として（遅延、縮小テストなど）品質に問題は無いか | H34: － | I34: － | L34: テスト項目書_
B35: =B34+1 -> 20 | D35: テスト規模が当初予定と乖離が発生していないか。している場合、その理由・根拠を管理できているか | H35: － | I35: － | L35: テスト項目書_進捗
B36: =B35+1 -> 21 | D36: 「概要」シート上の、「開発チーム実施対象テスト要否」(H列)が○となっているテストの実施が完了してるか | E36: -- | H36: － | I36: － | L36: テスト項目書_概要シート
B37: =B36+1 -> 22 | D37: テスト完了時点で評価可能なテスト有効性項目・テスト品質項目は、目標値を達成しているか、乖離している場合理由は明確に示されているか※ | H37: － | I37: － | L37: テスト項目書_チェック表
B38: =B37+1 -> 23 | D38: 同時並行の案件の機能バッティング、マージスケジュールの確認 | E38: -
B40: ※各指標の算出方法詳細はこちら
B41: 切り口 | C41: 大項目 | D41: 内容 | G41: 目標値 | H41: 備考
B42: テストの有効性を評価 | C42: テスト密度 | D42: システムを新規に開発した場合や、既存のシステムに対して機能追加を行った際に、実行するテストの量が十分であるかを測定・評価するための指標 計算式： テストケース数(件)÷プログラムの開発規模(kステップ) or 機能数 ※リグレッションテストも含むため、既存機能の改修の場合でも改修対象機能を開発規模とする(ケースにより変更) (例)テスト件数250件、プログラムの開発規模3,000行 = 3kステップ、機能数5の場合 ステップ換算：250÷3 = 83.33 機能数換算：250÷5 = 50 | G42: 基準値の80%以上 ※ステップ換算の場合、標準値を100としその80% の80 機能数換算の場合、 基準値30としその80%の24 | H42: 既存の軽微な改修が多いなどで、基準値を大きく乖離する場合は、内容をTLとすり合わせ問題ないことを確認
C43: バグ摘出率 | D43: 開発規模に対してどれくらいのバグを検出できているかを測定し、テストの有効性を評価するための指標 計算式：バグ数(件)※1÷プログラムの開発規模(kステップ)※2 ※1 テストのNG件数ではなくバグ件数 ※2 リグレッションテストも含むため、既存機能の改修の場合でも改修対象機能を開発規模とする(ケースにより変更)。 (例) バグ件数 15件、プログラムの開発規模 3,000行=3kステップの場合、機能数5の場合 ステップ換算：15 ÷ 3 = 5 機能数換算；15÷5 = 3 | G43: 標準値の80%以上120%以下 ※ステップ換算の場合、標準値を5としその80%-120%のため4-6 機能数換算の場合、 標準値を3としてその80%-120%のため2.4-3.6 | H43: 既存の軽微な改修が多いなどで、基準値を大きく乖離する場合は、内容をTLとすり合わせ問題ないことを確認。 特に理由がなく乖離している場合は強化テストの要否を検討する
C44: カバレッジ | D44: 修正対象のテストがどれだけカバーできているかの指標 シナリオテストでは下記の観点を検証 ◽️想定されるユースケース 今回の改修機能を利用した場合の主要ユースケース(可能な限り ブラックボックステストで実施) ◽️リグレッション観点 修正箇所に関連するメインユースケース | G44: 実施不可なものを除いて100% | H44: コードレベルのカバレッジをシナリオテストで担保するのは効率が悪いため、単体テストでカバーを前提と考える。そのため、手動テスト内では要件レベル・ユースケースレベル、関連するリグレッション観点での全網羅を目指す。
C45: 再テスト実施率 | D45: バグの修正によりシステムに手が入った場合は、すでに合格したケースについても再実施する必要があるが、それが適切に行われているかの評価 計算式： 再テスト実施件数÷バグを検知したテスト件数 (例) 再テスト実施件数 20 ÷ バグを検知したNGテスト件数 15 = 1.3333.. | G45: 1.2以上 | H45: 基準値大きく下回る場合は、中身をTLとすり合わせ問題ないことを確認。 目安値のため、この指標達成のために再テスト件数を増やす必要はない。
...

Sheet 【修正中】バグ発生率
A1: テストケース | B1: ='進捗'!P4 -> 123 | C1: ←進捗シートの総ケース数
A2: 現在のテスト消化数 | B2: ='進捗'!P4-'進捗'!O4 -> 123 | C2: ←進捗シートの総ケース数-残項目数
A3: 現在のテスト進捗 | B3: =IFERROR(B1/B2,0) -> 1
A4: 推定バグ検出率 | B4: 0.03
B6: ⭐︎ | D6: ⭐︎ | F6: ⭐︎ | G6: ⭐︎ | I6: ⭐︎ | J6: ⭐︎ | M6: ⭐︎
A7: 日付 | B7: 総テストケース数 | C7: テスト消化予定 | D7: テスト消化予定累計 | E7: テスト消化実績 | F7: テスト消化実績累計 | G7: バグ検出の推定数 | H7: バグ検出実績 | I7: バグ検出実績累積 | J7: バグ検出率 | K7: 解決済バグ件数 | L7: 解決済バグ累計 | M7: 未解決バグ
A8: 45391 | B8: =$B$1 -> 123 | C8: =B8/count($A$8:$A$22) -> 8.2 | D8: =C8 -> 8.2 | E8: 1 | F8: =E8 -> 1 | G8: =F8*$B$4 -> 0.03 | H8: =countif('バグ一覧'!D:D,"=A8") -> 0 | I8: =H8 -> 0 | J8: =I8/B8 -> 0 | K8: 0 | L8: =K8 -> 0 | M8: =I8-L8 -> 0
A9: =A8+1 -> 45392 | B9: =$B$1 -> 123 | C9: =B9/count($A$8:$A$22) -> 8.2 | D9: =C9+D8 -> 16.4 | E9: 2 | F9: =F8+E9 -> 3 | G9: =F9*$B$4 -> 0.09 | H9: =countif('バグ一覧'!D:D,"=A9") -> 0 | I9: =H9+I8 -> 0 | J9: =I9/B9 -> 0 | K9: 0 | L9: =K9+L8 -> 0 | M9: =I9-L9 -> 0
A10: =A9+1 -> 45393 | B10: =$B$1 -> 123 | C10: =B10/count($A$8:$A$22) -> 8.2 | D10: =C10+D9 -> 24.6 | E10: 10 | F10: =F9+E10 -> 13 | G10: =F10*$B$4 -> 0.39 | H10: =countif('バグ一覧'!D:D,"=A10") -> 0 | I10: =H10+I9 -> 0 | J10: =I10/B10 -> 0 | K10: 1 | L10: =K10+L9 -> 1 | M10: =I10-L10 -> -1
A11: =A10+1 -> 45394 | B11: =$B$1 -> 123 | C11: =B11/count($A$8:$A$22) -> 8.2 | D11: =C11+D10 -> 32.8 | E11: 11 | F11: =F10+E11 -> 24 | G11: =F11*$B$4 -> 0.72 | H11: =countif('バグ一覧'!D:D,"=A11") -> 0 | I11: =H11+I10 -> 0 | J11: =I11/B11 -> 0 | K11: 0 | L11: =K11+L10 -> 1 | M11: =I11-L11 -> -1
A12: =A11+1 -> 45395 | B12: =$B$1 -> 123 | C12: =B12/count($A$8:$A$22) -> 8.2 | D12: =C12+D11 -> 41 | E12: 12 | F12: =F11+E12 -> 36 | G12: =F12*$B$4 -> 1.08 | H12: =countif('バグ一覧'!D:D,"=A12") -> 0 | I12: =H12+I11 -> 0 | J12: =I12/B12 -> 0 | K12: 1 | L12: =K12+L11 -> 2 | M12: =I12-L12 -> -2
A13: =A12+1 -> 45396 | B13: =$B$1 -> 123 | C13: =B13/count($A$8:$A$22) -> 8.2 | D13: =C13+D12 -> 49.2 | E13: 8 | F13: =F12+E13 -> 44 | G13: =F13*$B$4 -> 1.32 | H13: =countif('バグ一覧'!D:D,"=A8") -> 0 | I13: =H13+I12 -> 0 | J13: =I13/B13 -> 0 | K13: 1 | L13: =K13+L12 -> 3 | M13: =I13-L13 -> -3
A14: =A13+1 -> 45397 | B14: =$B$1 -> 123 | C14: =B14/count($A$8:$A$22) -> 8.2 | D14: =C14+D13 -> 57.4 | E14: 9 | F14: =F13+E14 -> 53 | G14: =F14*$B$4 -> 1.59 | H14: =countif('バグ一覧'!D:D,"=A8") -> 0 | I14: =H14+I13 -> 0 | J14: =I14/B14 -> 0 | K14: 0 | L14: =K14+L13 -> 3 | M14: =I14-L14 -> -3
A15: =A14+1 -> 45398 | B15: =$B$1 -> 123 | C15: =B15/count($A$8:$A$22) -> 8.2 | D15: =C15+D14 -> 65.6 | E15: 10 | F15: =F14+E15 -> 63 | G15: =F15*$B$4 -> 1.89 | H15: =countif('バグ一覧'!D:D,"=A8") -> 0 | I15: =H15+I14 -> 0 | J15: =I15/B15 -> 0 | K15: 0 | L15: =K15+L14 -> 3 | M15: =I15-L15 -> -3
A16: =A15+1 -> 45399 | B16: =$B$1 -> 123 | C16: =B16/count($A$8:$A$22) -> 8.2 | D16: =C16+D15 -> 73.8 | E16: 11 | F16: =F15+E16 -> 74 | G16: =F16*$B$4 -> 2.22 | H16: =countif('バグ一覧'!D:D,"=A8") -> 0 | I16: =H16+I15 -> 0 | J16: =I16/B16 -> 0 | K16: 1 | L16: =K16+L15 -> 4 | M16: =I16-L16 -> -4
A17: =A16+1 -> 45400 | B17: =$B$1 -> 123 | C17: =B17/count($A$8:$A$22) -> 8.2 | D17: =C17+D16 -> 82 | E17: 12 | F17: =F16+E17 -> 86 | G17: =F17*$B$4 -> 2.58 | H17: =countif('バグ一覧'!D:D,"=A8") -> 0 | I17: =H17+I16 -> 0 | J17: =I17/B17 -> 0 | K17: 1 | L17: =K17+L16 -> 5 | M17: =I17-L17 -> -5
A18: =A17+1 -> 45401 | B18: =$B$1 -> 123 | C18: =B18/count($A$8:$A$22) -> 8.2 | D18: =C18+D17 -> 90.2 | E18: 8 | F18: =F17+E18 -> 94 | G18: =F18*$B$4 -> 2.82 | H18: =countif('バグ一覧'!D:D,"=A8") -> 0 | I18: =H18+I17 -> 0 | J18: =I18/B18 -> 0 | K18: 1 | L18: =K18+L17 -> 6 | M18: =I18-L18 -> -6
A19: =A18+1 -> 45402 | B19: =$B$1 -> 123 | C19: =B19/count($A$8:$A$22) -> 8.2 | D19: =C19+D18 -> 98.4 | E19: 9 | F19: =F18+E19 -> 103 | G19: =F19*$B$4 -> 3.09 | H19: =countif('バグ一覧'!D:D,"=A8") -> 0 | I19: =H19+I18 -> 0 | J19: =I19/B19 -> 0 | K19: 0 | L19: =K19+L18 -> 6 | M19: =I19-L19 -> -6
A20: =A19+1 -> 45403 | B20: =$B$1 -> 123 | C20: =B20/count($A$8:$A$22) -> 8.2 | D20: =C20+D19 -> 106.6 | E20: 10 | F20: =F19+E20 -> 113 | G20: =F20*$B$4 -> 3.39 | H20: =countif('バグ一覧'!D:D,"=A8") -> 0 | I20: =H20+I19 -> 0 | J20: =I20/B20 -> 0 | K20: 2 | L20: =K20+L19 -> 8 | M20: =I20-L20 -> -8
A21: =A20+1 -> 45404 | B21: =$B$1 -> 123 | C21: =B21/count($A$8:$A$22) -> 8.2 | D21: =C21+D20 -> 114.8 | E21: 20 | F21: =F20+E21 -> 133 | G21: =F21*$B$4 -> 3.99 | H21: =countif('バグ一覧'!D:D,"=A8") -> 0 | I21: =H21+I20 -> 0 | J21: =I21/B21 -> 0 | K21: 1 | L21: =K21+L20 -> 9 | M21: =I21-L21 -> -9
A22: =A21+1 -> 45405 | B22: =$B$1 -> 123 | C22: =B22/count($A$8:$A$22) -> 8.2 | D22: =C22+D21 -> 123 | E22: 20 | F22: =F21+E22 -> 153 | G22: =F22*$B$4 -> 4.59 | H22: =countif('バグ一覧'!D:D,"=A8") -> 0 | I22: =H22+I21 -> 0 | J22: =I22/B22 -> 0 | K22: 0 | L22: =K22+L21 -> 9 | M22: =I22-L22 -> -9
A23: 累計 | C23: =sum(C8:C22) -> 123 | E23: =sum(E8:E22) -> 153 | F23: =MAX(F8:F22) -> 153 | G23: =max(G8:G22) -> 4.59 | H23: =sum(H8:H22) -> 0 | I23: =max(I8:I22) -> 0 | K23: =sum(K8:K22) -> 9 | L23: =max(L8:L22) -> 9

Sheet 【修正中】テスト結果評価_テンプレ
A2: ①テストケース合格率
E3: テストケース数 | F3: バグ件数 | G3: 指標 | H3: 目標値
A4: 項目 | B4: テスト件数に対するバグの発生率 計算式：バグ件数÷テストケース数(再実施含まない) (例) テスト件数250件、検知したバグ15件 15÷250 = 6% | E4: 100 | F4: =sum(#REF!) -> #REF! | G4: =F4/E4% -> #REF! | H4: 3%未満
A5: 考察 | E5: - | F5: - | G5: - | H5: -
A7: ②バグの発生率
E8: テストケース数 | F8: バグ件数 | G8: 指標 | H8: 目標値
A9: 項目 | B9: テスト件数に対するバグの発生率 計算式：バグ件数÷テストケース数(再実施含まない) (例) テスト件数250件、検知したバグ15件 15÷250 = 6% | E9: 100 | F9: =sum(#REF!) -> #REF! | G9: =F9/E9% -> #REF! | H9: 3%未満
A10: 考察 | E10: - | F10: - | G10: - | H10: -

Sheet 【修正中】テスト有効性評価_テンプレ
A1: ①テスト密度
E2: テストケース数 | F2: プログラムの開発規模 | G2: 指標 | H2: 目標値
A3: 項目 | B3: システムを新規に開発した場合や、既存のシステムに対して機能追加を行った際に、実行するテストの量が十分であるかを測定・評価するための指標 計算式： テストケース数(件)÷プログラムの開発規模(kステップ) or 機能数 ※リグレッションテストも含むため、既存機能の改修の場合でも改修対象機能を開発規模とする(ケースにより変更) | E3: 240 | F3: 42 | G3: =E3/F3 -> 5.7142857 | I3: 基準値の80%以上 ※ステップ換算の場合、標準値を100としその80% の80 機能数換算の場合、 基準値30としその80%の24
A4: 考察 | E4: - | F4: - | G4: - | H4: -
A5: レビュアーチエック | E5: 問題なし | F5: - | G5: - | H5: -
A7: ②バグ摘出率
E8: バグ件数 | F8: プログラムの開発規模 | G8: 指標 | H8: 目標値
A9: 項目 | B9: 開発規模に対してどれくらいのバグを検出できているかを測定し、テストの有効性を評価するための指標 計算式：バグ数(件)※1÷プログラムの開発規模(kステップ)※2 ※1 テストのNG件数ではなくバグ件数 ※2 リグレッションテストも含むため、既存機能の改修の場合でも改修対象機能を開発規模とする(ケースにより変更)。 (例) バグ件数 15件、プログラムの開発規模 3,000行=3kステップの場合、機能数5の場合 ステップ換算：15 ÷ 3 = 5 機能数換算；15÷5 = 3 | E9: 5 | F9: 60 | G9: =E9/F9 -> 0.083333333 | H9: 3%未満
A10: 考察 | E10: - | F10: - | G10: - | H10: -
A12: ③再テスト実施率
E13: 再テスト実施件数 | F13: NGテスト件数 | G13: 指標 | H13: 目標値
A14: 項目 | B14: バグの修正によりシステムに手が入った場合は、すでに合格したケースについても再実施する必要があるが、それが適切に行われているかの評価 計算式： 再テスト実施件数÷バグを検知したテスト件数 (例) 再テスト実施件数 20 ÷ バグを検知したNGテスト件数 15 = 1.3333.. | E14: 240 | F14: 60 | G14: =E14/F14 -> 4 | H14: 1.2以上
A15: 考察 | E15: - | F15: - | G15: - | H15: -
A17: https://github.com/TOKIUM/keihi/pull/25212/checks
A18: ファイル数 | B18: 60
A19: コード数 | B19: 41564行 | C19: 41.5K
